Workbook

Sheet Control Center
A1: ATL EMPLOYEE SCHEDULER 3.1 — PHASE 2 (AM ENGINE)
A3: Schedule Date | B3: 46264 | D3: BASELINE RULES
A4: AM Surveys Needed? | B4: Y | D4: Fill all 43 Client Required slots before playbook-only positions.
A5: PM Surveys Needed? | B5: Y | D5: Leads excluded from designated posts and break relief.
A6: Required Client Slots | B6: 43 | D6: Main Inside requires qualification = Y.
A7: Physical Positions | B7: 39 | D7: Fixed/day-specific/mobility/wheelchair restrictions are hard controls.
A8: Survey Slots | B8: 4 | D8: Mentor + trainee are one same-shift staffing unit.
D9: AM honors HARD 3:45 OPEN and START 5:45.
A10: Phase Status: | B10: Limited in-zone tap-outs: 1 per Main/South/North/LN/Divest. Breaks still with leads. | D10: PM honors 12:15 / 2:00 handoff rules.
A11: Next: | B11: 3:45 cycles to easier same-zone post; 5:45 covers the demanding open. | D11: Relief configuration remains editable; Rover/Relief is allowed.
A12: OFFICIAL OUTPUT FORMAT: Client Assignment Sheet + Operations Playbook match lead-familiar templates; do not restyle. | D12: Phase 1: Data foundation only. No VBA. Self-contained (no external links). AM engine next.
A13: HOW TO RECALC AFTER CHANGING DATE:
A14: HOW MANAGERS USE THIS SHARED FILE (OneDrive — no macros)
A15: ROLES
A16: • Schedule owner (1–2 people): maintains Employee Master & Approved Absences; requests/runs assignment rebuild when the date or roster changes materially.
A17: • Floor leads / managers: set or confirm Schedule Date; read AM/PM Operations Playbooks; adjust individual posts via dropdowns if needed; print for the shift.
A19: DAILY STEPS
A20: 1. Open this workbook from OneDrive in desktop Excel (best formula reliability). Excel for the web may not recalculate everything the same way.
A21: 2. Set Schedule Date in Control Center (yellow cell). Confirm AM Surveys / PM Surveys flags and Pax if used.
A22: 3. Ensure Formulas → Calculation Options → Automatic. Pools and Available flags should update with the date (no macros).
A23: 4. Check AM Pool / PM Pool sheets — filter column A = Y and confirm headcount looks right for the day.
A24: 5. Use the current AM Operations Playbook and PM Operations Playbook for assignments. Right side = full ops after reinforcement/handoff.
A25: 6. Optional: tweak a name using the dropdown on a playbook cell if someone calls out or swaps. Do not invent posts outside the playbook structure.
... A42: Owners: change date → confirm pools → rebuild AM then PM engines → save to OneDrive. Managers do not need Ctrl+Alt+F5 for normal reading if Automatic calc is on.

Sheet Manager Run Sheet
A1: MANAGER RUN SHEET — DAILY PLAYBOOK
A3: Step | B3: Action
A4: 1. SET DATE | B4: Control Center → set Schedule Date (B3) to the operating day.
A5: 2. SURVEYS | B5: Set AM Surveys (B4) and PM Surveys (B5) to Y or N.
A6: 3. ABSENCES | B6: Add call-outs / approved time off on Approved Absences (name, start, end).
A7: 4. RECALC | B7: Ctrl+Alt+F5 (or Data → Calculate Now) so pools refresh.
A8: 5. CHECK POOLS | B8: AM Pool / PM Pool → filter column A = Y. Confirm headcount.
A9: 6. AM PLAYBOOK | B9: Confirm HARD 3:45 opens, full ops right side, lunch/notes.
A10: 7. PM PLAYBOOK | B10: Confirm handoff: 3:45 full-ops → 12:15; 5:45 full-ops → 2:00.
A11: 8. BREAKS | B11: Leads manage lunches in-zone. Break Coverage sheets are parked.
A12: 9. CLIENT OUTPUT | B12: Client Assignment Sheet → print AM block or PM block for client.
A13: 10. PRINT | B13: Print Preview; fit width 1 page. Clear extra scaling if text is tiny.
A14: 11. LEADS | B14: Enter lead names in yellow Leads box on AM and PM playbooks.
... A17: 14. ARCHIVE | B17: File → Save As dated copy (e.g. ATL_Playbook_2026-08-26.xlsx).
A19: IMPORTANT
A20: • Client Assignment Sheet never invents names — only Playbooks assign. • Do not overwrite Employee Master pool formulas. • Call-outs go to Approved Absences → Recalc → re-check playbooks. • UNFILLED on a required post = fill from dropdown or call in coverage.
A22: SHEET MAP
A23: Sheet | B23: Purpose
A24: Control Center | B24: Date, survey switches
A25: Manager Run Sheet | B25: This daily checklist
A26: Validation | B26: Pass/fail + live pool counts
A27: Client Assignment Sheet | B27: AM/PM views for client (from playbooks)
A28: AM / PM Operations Playbook | B28: Daily assignments
A29: Break Coverage / PM Break Coverage | B29: Lunch relief matrices
A30: AM Pool / PM Pool | B30: Eligible today
A31: Employee Master | B31: People, quals, shifts
A32: Approved Absences | B32: Time off / call-outs
A33: Position Library | B33: HARD open, PM handoff rules
A34: Break Relief Guide | B34: Who covers whose lunch

Sheet PM Operations Playbook
A1: PM OPERATIONS PLAYBOOK — POSITION FLOW
A2: Date: | B2: ='Control Center'!B3 | D2: Pax:
A3: Leads:
A4: Leads manage breaks in-zone. Handoff follows AM FULL OPS (right side after any tap-out): 3:45 still on post → 12:15 · 5:45 on post → 2:00.
A5: Name (12:15) | B5: Shift | C5: POSITION | D5: Full ops name | E5: Shift | F5: Notes
A6: MAIN SECURITY CHECKPOINT
A7: Agnes Bammannage | B7: 12:15 PM | C7: Front Entrance (#1) | D7: Agnes Bammannage | E7: 12:15 PM | F7: Handoff from Mamadou Seck (5:45 AM)
C8: Front Entrance (#2) | D8: Aaliyah Snider | E8: 2:00 PM | F8: Handoff from Ahamed John (3:45 AM)
A9: Alyssa Prince | B9: 12:15 PM | C9: ADA Entrance (1) | D9: Alyssa Prince | E9: 12:15 PM | F9: Handoff from Allen Suggs (3:45 AM)
A10: Amadou Diallo | B10: 12:15 PM | C10: Lanes 17-18 (1) | D10: Amadou Diallo | E10: 12:15 PM | F10: Handoff from Benjamin Crosby (3:45 AM)
A11: Darrius Dunlap | B11: 12:15 PM | C11: Inside Center (1) | D11: Darrius Dunlap | E11: 12:15 PM | F11: Handoff from Demetrius Thomas (3:45 AM)
C12: Lanes 1-3/Pre-Check (1) | D12: Akuugo Nduaguba | E12: 2:00 PM | F12: Handoff from Abdou Mballo (5:45 AM)
A13: ATRIUM
A14: Betelhem Wubshet | B14: 12:15 PM | C14: KIA (1) | D14: Betelhem Wubshet | E14: 12:15 PM | F14: Handoff from Natasha Carbon (3:45 AM)
A15: SOUTH SECURITY CHECKPOINT
A16: Brittney Quave | B16: 12:15 PM | C16: Checkpoint – Front Entrance (#1) | D16: Brittney Quave | E16: 12:15 PM | F16: Handoff from Brianna Bryant (3:45 AM)
A17: Chiedu Memeh | B17: 12:15 PM | C17: Checkpoint – Front Entrance (#2) | D17: Chiedu Memeh | E17: 12:15 PM | F17: Handoff from Tanya Organ (3:45 AM)
A18: David Holloman | B18: 12:15 PM | C18: Checkpoint – Inside (#1) | D18: David Holloman | E18: 12:15 PM | F18: Handoff from Ashia Norman (5:45 AM)
C19: Checkpoint – Inside (#2) | F19: Not staffed (PM)
C20: Hallway Pre-check Overflow (1) | D20: Amanda Scott | E20: 2:00 PM | F20: Handoff from Anariah Daniel (5:45 AM)
C21: South Restroom (1) | D21: Ashley Lazenby | E21: 2:00 PM | F21: Handoff from Micheal Manning (5:45 AM)
C22: IHOP (1) | D22: Braheem Wooden | E22: 2:00 PM | F22: Handoff from Brittany Gaither (3:45 AM)
A23: NORTH SECURITY CHECKPOINT
A24: De'Anna Reese | B24: 12:15 PM | C24: Checkpoint – Inside (1) | D24: De'Anna Reese | E24: 12:15 PM | F24: Handoff from Dequavius Parker (5:45 AM)
A25: Eyerusalem Esubaluw | B25: 12:15 PM | C25: North Corridor (1) | D25: Eyerusalem Esubaluw | E25: 12:15 PM | F25: Handoff from Brian Lee (5:45 AM)
C26: North Restroom Hallway (#1) | D26: Cheikh Sylla | E26: 2:00 PM | F26: Handoff from Mildred Torres (5:45 AM)
C27: North Restroom Hallway (#2) | D27: Chris Jungson | E27: 2:00 PM | F27: Handoff from Bintou Gueye (5:45 AM)
C28: We Juice It (1) | D28: Dezeraye Fedrick | E28: 2:00 PM | F28: Handoff from Khadijah Van Holten (3:45 AM)
A29: LOWER NORTH SECURITY CHECKPOINT
A30: Falana Broughton | B30: 12:15 PM | C30: Checkpoint – Inside (1) | D30: Falana Broughton | E30: 12:15 PM | F30: Handoff from Dequavius Parker (5:45 AM)
C31: N5 Door (1) | D31: Elizabeth Harlee | E31: 2:00 PM | F31: Handoff from David Scoggin (5:45 AM)
C32: LN2 Elevator (1) | D32: Kaci Cosper | E32: 2:00 PM | F32: Handoff from Kimberly Morrison (3:45 AM)
A33: AGT LEVEL
C34: T Platform Train Doors (#1) | D34: Khursheeda Nasreen | E34: 2:00 PM | F34: Handoff from Derika Phipps (5:45 AM)
C35: T Platform Train Doors (#2) | D35: Kori Jenkins | E35: 2:00 PM | F35: Handoff from Feleke Tekle (5:45 AM)
C36: Domestic Baggage Claim (1) | D36: Oumou Sane | E36: 2:00 PM | F36: Handoff from Monica Ortiz (5:45 AM)
C37: T Bridge Landing (#1) | D37: Princess Vance | E37: 2:00 PM | F37: Handoff from Fikre Hadera (5:45 AM)
C38: T Bridge Landing (#2) | D38: Theresa Logan | E38: 2:00 PM | F38: Handoff from Habtewold Daba (5:45 AM)
C39: Alpha West (1) | D39: Timicha Marshall | E39: 2:00 PM | F39: Handoff from Isaiah Williams (5:45 AM)
C40: Bravo West (1) | D40: Yitshhaq Sagahon | E40: 2:00 PM | F40: Handoff from Jada Batiste (5:45 AM)
...

Sheet AM Operations Playbook
A1: AM OPERATIONS PLAYBOOK — POSITION FLOW
A2: Date: | B2: ='Control Center'!B3 | D2: Pax:
A3: Leads:
A4: Leads manage breaks in-zone. Limited tap-outs (1 per zone) from demanding open to easier same-zone post. White=stays · Light blue=3:45 who moved · Green=5:45 covering the open · Orange=UNFILLED.
A5: Name (3:45) | B5: Shift | C5: POSITION | D5: Full ops name | E5: Shift | F5: Notes
A6: MAIN SECURITY CHECKPOINT
A7: Ahamed John | B7: 3:45 AM | C7: Front Entrance (#1) | D7: Mamadou Seck | E7: 5:45 AM | F7: Tap-out → Front Entrance (#2)
A8: Ahamed John | B8: 3:45 AM | C8: Front Entrance (#2) | D8: Ahamed John | E8: 3:45 AM | F8: From Front Entrance (#1)
A9: Allen Suggs | B9: 3:45 AM | C9: ADA Entrance (1) | D9: Allen Suggs | E9: 3:45 AM | F9: Open
A10: Benjamin Crosby | B10: 3:45 AM | C10: Lanes 17-18 (1) | D10: Benjamin Crosby | E10: 3:45 AM | F10: Open
A11: Demetrius Thomas | B11: 3:45 AM | C11: Inside Center (1) | D11: Demetrius Thomas | E11: 3:45 AM | F11: Open
C12: Lanes 1-3/Pre-Check (1) | D12: Abdou Mballo | E12: 5:45 AM | F12: Start 5:45
A13: ATRIUM
A14: Natasha Carbon | B14: 3:45 AM | C14: KIA (1) | D14: Natasha Carbon | E14: 3:45 AM | F14: Zone mix
A15: SOUTH SECURITY CHECKPOINT
A16: Brianna Bryant | B16: 3:45 AM | C16: Checkpoint – Front Entrance (#1) | D16: Brianna Bryant | E16: 3:45 AM | F16: Open
A17: Tanya Organ | B17: 3:45 AM | C17: Checkpoint – Front Entrance (#2) | D17: Tanya Organ | E17: 3:45 AM | F17: Zone mix
A18: Brittany Gaither | B18: 3:45 AM | C18: Checkpoint – Inside (#1) | D18: Ashia Norman | E18: 5:45 AM | F18: Tap-out → IHOP (1)
C19: Checkpoint – Inside (#2) | D19: Aleah Mckinnon | E19: 5:45 AM | F19: Start 5:45
C20: Hallway Pre-check Overflow (1) | D20: Anariah Daniel | E20: 5:45 AM | F20: Start 5:45
C21: South Restroom (1) | D21: Micheal Manning | E21: 5:45 AM | F21: Zone mix
A22: Brittany Gaither | B22: 3:45 AM | C22: IHOP (1) | D22: Brittany Gaither | E22: 3:45 AM | F22: From Checkpoint – Inside (#1)
A23: NORTH SECURITY CHECKPOINT
A24: Jessika Williams | B24: 3:45 AM | C24: Checkpoint – Inside (1) | D24: Jessika Williams | E24: 3:45 AM | F24: Open
A25: Khadijah Van Holten | B25: 3:45 AM | C25: North Corridor (1) | D25: Brian Lee | E25: 5:45 AM | F25: Tap-out → We Juice It (1)
C26: North Restroom Hallway (#1) | D26: Mildred Torres | E26: 5:45 AM | F26: Zone mix
C27: North Restroom Hallway (#2) | D27: Bintou Gueye | E27: 5:45 AM | F27: Start 5:45
A28: Khadijah Van Holten | B28: 3:45 AM | C28: We Juice It (1) | D28: Khadijah Van Holten | E28: 3:45 AM | F28: From North Corridor (1)
A29: LOWER NORTH SECURITY CHECKPOINT
A30: Kimberly Morrison | B30: 3:45 AM | C30: Checkpoint – Inside (1) | D30: Dequavius Parker | E30: 5:45 AM | F30: Tap-out → LN2 Elevator (1)
C31: N5 Door (1) | D31: David Scoggin | E31: 5:45 AM | F31: Start 5:45
A32: Kimberly Morrison | B32: 3:45 AM | C32: LN2 Elevator (1) | D32: Kimberly Morrison | E32: 3:45 AM | F32: From Checkpoint – Inside (1)
A33: AGT LEVEL
C34: T Platform Train Doors (#1) | D34: Derika Phipps | E34: 5:45 AM | F34: Start 5:45
C35: T Platform Train Doors (#2) | D35: Feleke Tekle | E35: 5:45 AM | F35: Start 5:45
C36: Domestic Baggage Claim (1) | D36: Monica Ortiz | E36: 5:45 AM | F36: Zone mix
C37: T Bridge Landing (#1) | D37: Fikre Hadera | E37: 5:45 AM | F37: Start 5:45
C38: T Bridge Landing (#2) | D38: Habtewold Daba | E38: 5:45 AM | F38: Start 5:45
C39: Alpha West (1) | D39: Isaiah Williams | E39: 5:45 AM | F39: Start 5:45
C40: Bravo West (1) | D40: Jada Batiste | E40: 5:45 AM | F40: Start 5:45
...

Sheet Client Assignment Sheet
A1: CLIENT ASSIGNMENT SHEET — FROM AM / PM PLAYBOOKS ONLY
A2: Date: | B2: ='Control Center'!B3
A3: NEVER assigns employees. Names copied from playbooks only. Fix assignments on AM/PM Operations Playbook, then re-open or re-export this sheet. Print AM block or PM block as needed.
A5: AM CLIENT VIEW — AM Operations Playbook (3:45 | full ops after 5:45)
A6: # | B6: POSITION | C6: Name (3:45) | D6: Shift | E6: Name (5:45 full ops) | F6: Shift | G6: Source
A7: MAIN SECURITY CHECKPOINT
A8: 1 | B8: Front Entrance (#1) | C8: Khadijah Van Holten | D8: 3:45 AM | E8: Kidest Solomon | F8: 5:45 AM | G8: AM Playbook
A9: 2 | B9: Front Entrance (#2) | C9: Maryse Camille | D9: 3:45 AM | E9: Maryse Camille | F9: 3:45 AM | G9: AM Playbook
A10: 3 | B10: ADA Entrance (1) | C10: Larry Fuller | D10: 3:45 AM | E10: Shanta Islam | F10: 5:45 AM | G10: AM Playbook
A11: 4 | B11: Lanes 17-18 (1) | C11: Tiffany Felton | D11: 3:45 AM | E11: Tiffany Felton | F11: 3:45 AM | G11: AM Playbook
A12: 5 | B12: Inside Center (1) | C12: Demetrius Thomas | D12: 3:45 AM | E12: Demetrius Thomas | F12: 3:45 AM | G12: AM Playbook
A13: 6 | B13: Lanes 1-3/Pre-Check (1) | E13: Jada Batiste | F13: 5:45 AM | G13: AM Playbook
A14: ATRIUM
A15: 7 | B15: KIA (1) | C15: Natasha Carbon | D15: 3:45 AM | E15: Natasha Carbon | F15: 3:45 AM | G15: AM Playbook
A16: SOUTH SECURITY CHECKPOINT
A17: 8 | B17: Checkpoint – Front Entrance (#1) | E17: Lynn Yi-Smith | F17: 5:45 AM | G17: AM Playbook
A18: 9 | B18: Checkpoint – Front Entrance (#2) | C18: Brianna Bryant | D18: 3:45 AM | E18: Brianna Bryant | F18: 3:45 AM | G18: AM Playbook
A19: 10 | B19: Checkpoint – Inside (#1) | C19: Maryse Camille | D19: 3:45 AM | E19: Sarita Jewell | F19: 5:45 AM | G19: AM Playbook
A20: 11 | B20: Checkpoint – Inside (#2) | E20: Jamal Reynolds | F20: 5:45 AM | G20: AM Playbook
A21: 12 | B21: Hallway Pre-check Overflow (1) | C21: Kimberly Morrison | D21: 3:45 AM | E21: Kimberly Morrison | F21: 3:45 AM | G21: AM Playbook
A22: 13 | B22: South Restroom (1) | C22: Jessika Williams | D22: 3:45 AM | E22: Jessika Williams | F22: 3:45 AM | G22: AM Playbook
A23: 14 | B23: IHOP (1) | C23: Khadijah Van Holten | D23: 3:45 AM | E23: Khadijah Van Holten | F23: 3:45 AM | G23: AM Playbook
A24: NORTH SECURITY CHECKPOINT
A25: 15 | B25: Checkpoint – Inside (1) | C25: Kimberly Morrison | D25: 3:45 AM | E25: Ashia Norman | F25: 5:45 AM | G25: AM Playbook
A26: 16 | B26: North Corridor (1) | C26: Benjamin Crosby | D26: 3:45 AM | E26: Benjamin Crosby | F26: 3:45 AM | G26: AM Playbook
A27: 17 | B27: North Restroom Hallway (#1) | C27: Tanya Organ | D27: 3:45 AM | E27: Tanya Organ | F27: 3:45 AM | G27: AM Playbook
A28: 18 | B28: North Restroom Hallway (#2) | C28: Ahamed John | D28: 3:45 AM | E28: Ahamed John | F28: 3:45 AM | G28: AM Playbook
A29: 19 | B29: We Juice It (1) | C29: Larry Fuller | D29: 3:45 AM | E29: Larry Fuller | F29: 3:45 AM | G29: AM Playbook
A30: LOWER NORTH SECURITY CHECKPOINT
A31: 20 | B31: Checkpoint – Inside (1) | C31: Jessika Williams | D31: 3:45 AM | E31: Adeyeye Opaaje | F31: 5:45 AM | G31: AM Playbook
A32: 21 | B32: N5 Door (1) | C32: UNFILLED | E32: Habtewold Daba | F32: 5:45 AM | G32: AM Playbook
A33: 22 | B33: LN2 Elevator (1) | E33: Vanessa Cortes | F33: 5:45 AM | G33: AM Playbook
A34: AGT LEVEL
A35: 23 | B35: T Platform Train Doors (#1) | E35: Mildred Torres | F35: 5:45 AM | G35: AM Playbook
A36: 24 | B36: T Platform Train Doors (#2) | E36: Monique Hicks | F36: 5:45 AM | G36: AM Playbook
A37: 25 | B37: Domestic Baggage Claim (1) | E37: Mamadou Seck | F37: 5:45 AM | G37: AM Playbook
A38: 26 | B38: T Bridge Landing (#1) | E38: Aleah Mckinnon | F38: 5:45 AM | G38: AM Playbook
A39: 27 | B39: T Bridge Landing (#2) | E39: Monica Ortiz | F39: 5:45 AM | G39: AM Playbook
A40: 28 | B40: Alpha West (1) | E40: Yahkirah Manggrum | F40: 5:45 AM | G40: AM Playbook
A41: 29 | B41: Bravo West (1) | E41: Isaiah Williams | F41: 5:45 AM | G41: AM Playbook
...

Sheet Break Coverage
A1: AM BREAK COVERAGE — DEFERRED TO LEADS
A2: Lunch/break assignment is handled by leads in each work zone. Parked for a later phase.
A4: Position | B4: Employee | C4: Side | D4: Lunch | E4: Relief By | F4: Relief From | G4: Status
A5: Domestic Baggage Claim (1) | B5: Mamadou Seck | C5: 5:45 | D5: 10:00 | E5: NO RELIEF | G5: NO RELIEF
A6: Checkpoint – Inside (1) | B6: Jessika Williams | C6: 3:45 | D6: 8:00 | E6: NO RELIEF | G6: NO RELIEF
A7: We Juice It (1) | B7: Larry Fuller | C7: 3:45 | D7: 8:00 | E7: NO RELIEF | G7: NO RELIEF
A8: Checkpoint – Inside (1) | B8: Adeyeye Opaaje | C8: 5:45 | D8: 9:00 | E8: NO RELIEF | G8: NO RELIEF
A9: Lanes 17-18 (1) | B9: Tiffany Felton | C9: 3:45 | D9: 9:00 | E9: NO RELIEF | G9: NO RELIEF
A10: North Divesting (#1) | B10: Natasha Carbon | C10: 3:45 | D10: 9:00 | E10: NO RELIEF | G10: NO RELIEF
A11: North Divesting (#2) | B11: George Whitehead | C11: 5:45 | D11: 9:00 | E11: NO RELIEF | G11: NO RELIEF
A12: North Divesting (#3) | B12: Moneshia Echols | C12: 3:45 | D12: 9:00 | E12: NO RELIEF | G12: NO RELIEF
A13: North Restroom Hallway (#1) | B13: Tanya Organ | C13: 3:45 | D13: 9:00 | E13: NO RELIEF | G13: NO RELIEF
A14: ADA Entrance (1) | B14: Shanta Islam | C14: 5:45 | D14: 10:00 | E14: Khadijah Van Holten | F14: Front Entrance (#1) | G14: OK
A15: Checkpoint – Front Entrance (#1) | B15: Lynn Yi-Smith | C15: 5:45 | D15: 10:00 | E15: Maryse Camille | F15: Checkpoint - Front Entrance (#2) | G15: OK
A16: Checkpoint – Inside (#1) | B16: Sarita Jewell | C16: 5:45 | D16: 10:00 | E16: Jamal Reynolds | F16: Checkpoint - Inside (#2) | G16: OK
A17: LN2 Elevator (1) | B17: Vanessa Cortes | C17: 5:45 | D17: 10:00 | E17: Larry Fuller | F17: We Juice It (1) | G17: OK
A18: Lower North Divesting (#2) | B18: Samiroe Ford | C18: 5:45 | D18: 10:00 | E18: Anariah Daniel | F18: Rover | G18: OK
A19: Lower North Divesting (#3) | B19: Tyana Gutzmore | C19: 5:45 | D19: 10:00 | E19: Brian Lee | F19: Rover | G19: OK
A20: North Divesting (#4) | B20: Micheal Manning | C20: 5:45 | D20: 10:00 | E20: Ahamed John | F20: North Restroom Hallway (#2) | G20: OK
A21: T Bridge Landing (#2) | B21: Monica Ortiz | C21: 5:45 | D21: 10:00 | E21: Aleah Mckinnon | F21: T Bridge Landing (#1) | G21: OK
A22: T Platform Train Doors (#1) | B22: Mildred Torres | C22: 5:45 | D22: 10:00 | E22: Dequavius Parker | F22: Rover | G22: OK
A23: T Platform Train Doors (#2) | B23: Monique Hicks | C23: 5:45 | D23: 10:00 | E23: Lashawn Jones | F23: Rover | G23: OK
A24: ADA Entrance (1) | B24: Larry Fuller | C24: 3:45 | D24: 8:00 | E24: Kidest Solomon | F24: Front Entrance (#1) | G24: OK
A25: Checkpoint – Front Entrance (#2) | B25: Brianna Bryant | C25: 3:45 | D25: 8:00 | E25: Anariah Daniel | F25: Rover | G25: OK
... A41: T Bridge Landing (#1) | B41: Aleah Mckinnon | C41: 5:45 | D41: 9:00 | E41: Monica Ortiz | F41: T Bridge Landing (#2) | G41: OK
A42: Alpha West (1) | B42: Yahkirah Manggrum | C42: 5:45 | D42: 10:00 | E42: No Relief Needed | G42: N/A
A43: Charlie West (1) | B43: Marquise Jackson | C43: 5:45 | D43: 10:00 | E43: No Relief Needed | G43: N/A
A44: Information Desk Personnel | B44: Sandra Gerson | C44: 5:45 | D44: 10:00 | E44: No Relief Needed | G44: N/A
A45: Bravo West (1) | B45: Isaiah Williams | C45: 5:45 | D45: 9:00 | E45: No Relief Needed | G45: N/A
A46: Delta West (1) | B46: Feleke Tekle | C46: 5:45 | D46: 9:00 | E46: No Relief Needed | G46: N/A
A47: KIA (1) | B47: Natasha Carbon | C47: 3:45 | D47: 9:00 | E47: No Relief Needed | G47: N/A
A48: Surveyor (#1) | B48: Chrystol Harvey | C48: 5:45 | D48: 9:00 | E48: No Relief Needed | G48: N/A
A49: Surveyor (#2) | B49: Cicely Thicklin | C49: 5:45 | D49: 9:00 | E49: No Relief Needed | G49: N/A
A50: Surveyor (#3) | B50: Jacquatta Green | C50: 5:45 | D50: 9:00 | E50: No Relief Needed | G50: N/A
A51: Rover | B51: Sara Alemu | C51: 5:45 | D51: 10:00 | E51: — (covers 2/2) | G51: ROVER
A52: Rover | B52: Shawanda Webb | C52: 5:45 | D52: 10:00 | E52: — (covers 2/2) | G52: ROVER
A53: Rover | B53: Veronda Jones | C53: 5:45 | D53: 10:00 | E53: — (covers 2/2) | G53: ROVER
... A57: Rover | B57: Lashawn Jones | C57: 5:45 | D57: 9:00 | E57: — (covers 2/2) | G57: ROVER
A59: Total: 53 | OK: 28 | No Relief Needed: 9 | NO RELIEF gaps: 9
A61: ROVER LOAD (AM max 2 covers each)
...

Sheet PM Break Coverage
A1: PM BREAK COVERAGE — DEFERRED TO LEADS
A2: Lunch/break assignment is handled by leads in each work zone. Parked for a later phase.
A4: Position | B4: Employee | C4: Side | D4: Lunch | E4: Relief By | F4: Relief From | G4: Status
A5: North Corridor (1) | B5: Zinash Shiferaw | C5: 12:15 | D5: 4:00 | E5: NO RELIEF | G5: NO RELIEF
A6: North Restroom Hallway (#1) | B6: Eyerusalem Esubaluw | C6: 12:15 | D6: 4:00 | E6: NO RELIEF | G6: NO RELIEF
A7: North Restroom Hallway (#2) | B7: John Davis | C7: 12:15 | D7: 4:00 | E7: NO RELIEF | G7: NO RELIEF
A8: We Juice It (1) | B8: Ivory Johnson | C8: 12:15 | D8: 4:00 | E8: NO RELIEF | G8: NO RELIEF
A9: Lower North Divesting (#3) | B9: Akuugo Nduaguba | C9: 2:00 | D9: 6:00 | E9: NO RELIEF | G9: NO RELIEF
A10: N5 Door (1) | B10: Kori Jenkins | C10: 2:00 | D10: 6:00 | E10: NO RELIEF | G10: NO RELIEF
A11: Front Entrance (#2) | B11: Chiedu Memeh | C11: 12:15 | D11: 4:00 | E11: Elizabeth Harlee | F11: Front Entrance (#1) | G11: OK
A12: IHOP (1) | B12: Brittney Quave | C12: 12:15 | D12: 4:00 | E12: Rihana Ababulla | F12: Rover | G12: OK
A13: Inside Center (1) | B13: De'Anna Reese | C13: 12:15 | D13: 4:00 | E13: Khalia Mitchell | F13: Front Entrance (#1) | G13: OK
A14: Lanes 17-18 (1) | B14: Veronica Laster | C14: 12:15 | D14: 4:00 | E14: Amadou Diallo | F14: Front Entrance (#2) | G14: OK
A15: Checkpoint – Front Entrance (#2) | B15: Amadou Diallo | C15: 12:15 | D15: 5:00 | E15: Elizabeth Harlee | F15: Checkpoint - Front Entrance (#1) | G15: OK
A16: Hallway Pre-check Overflow (1) | B16: Agnes Bammannage | C16: 12:15 | D16: 5:00 | E16: Brittney Quave | F16: IHOP (1) | G16: OK
A17: Lower North Divesting (#1) | B17: Elena Thomas | C17: 12:15 | D17: 5:00 | E17: Ivory Johnson | F17: We Juice It (1) | G17: OK
A18: North Divesting (#3) | B18: Darrius Dunlap | C18: 12:15 | D18: 5:00 | E18: Eyerusalem Esubaluw | F18: North Restroom Hallway (#1) | G18: OK
A19: South Restroom (1) | B19: Carrie Weaver | C19: 12:15 | D19: 5:00 | E19: David Holloman | F19: KIA (1) | G19: OK
A20: ADA Entrance (1) | B20: Theresa Logan | C20: 2:00 | D20: 6:00 | E20: Elizabeth Harlee | F20: Front Entrance (#1) | G20: OK
A21: Checkpoint – Front Entrance (#1) | B21: Khalia Mitchell | C21: 2:00 | D21: 6:00 | E21: Chiedu Memeh | F21: Checkpoint - Front Entrance (#2) | G21: OK
A22: Checkpoint – Inside (#1) | B22: Zekiah Robinson | C22: 2:00 | D22: 6:00 | E22: Alyssa Prince | F22: Rover | G22: OK
... A35: T Platform Train Doors (#1) | B35: Youssouf Traore | C35: 2:00 | D35: 7:00 | E35: Richard Soro | F35: T Platform Train Doors (#2) | G35: OK
A36: KIA (1) | B36: David Holloman | C36: 12:15 | D36: 4:00 | E36: No Relief Needed | G36: N/A
A37: Surveyor (#2) | B37: Kaba Diop | C37: 12:15 | D37: 4:00 | E37: No Relief Needed | G37: N/A
A38: Surveyor (#1) | B38: Falana Broughton | C38: 12:15 | D38: 5:00 | E38: No Relief Needed | G38: N/A
A39: Charlie West (1) | B39: Khursheeda Nasreen | C39: 2:00 | D39: 6:00 | E39: No Relief Needed | G39: N/A
A40: Alpha West (1) | B40: Heather Wray | C40: 2:00 | D40: 7:00 | E40: No Relief Needed | G40: N/A
A41: Bravo West (1) | B41: Braheem Wooden | C41: 2:00 | D41: 7:00 | E41: No Relief Needed | G41: N/A
A42: Delta West (1) | B42: Rozita Davis | C42: 2:00 | D42: 7:00 | E42: No Relief Needed | G42: N/A
A43: Rover | B43: Alyssa Prince | C43: 12:15 | D43: 4:00 | E43: — (covers 2/3) | G43: ROVER
A44: Rover | B44: Rihana Ababulla | C44: 12:15 | D44: 5:00 | E44: — (covers 3/3) | G44: ROVER
A46: Total: 40 | OK: 25 | No Relief Needed: 7 | NO RELIEF gaps: 6
A48: ROVER LOAD (PM max 3)
A49: Rihana Ababulla (12:15 PM) — covers 3/3 | own lunch 5:00 | by window {'4:00': 1, '6:00': 1, '7:00': 1}
A50: Alyssa Prince (12:15 PM) — covers 2/3 | own lunch 4:00 | by window {'6:00': 1, '7:00': 1}
A52: Lunch window counts: {'7:00': 11, '4:00': 11, '6:00': 11, '5:00': 7}

Sheet Validation
A1: VALIDATION & SMOKE-TEST CHECKLIST
A2: After date change or playbook regen: Ctrl+Alt+F5, then complete checklist.
A4: Check | B4: What to verify | C4: Pass Y/N | D4: Notes
A5: Date linked | B5: Control Center B3 drives Scheduled Today?
A6: AM pool > 0 | B6: AM Pool filter A=Y on a normal weekday
A7: PM pool > 0 | B7: PM Pool filter A=Y on a normal weekday
A8: No days-off on playbook | B8: Spot-check Days Off vs assignments
A9: No absences on playbook | B9: Approved Absences names not assigned
A10: Leads not on normal posts | B10: Lead=Y only in Leads box
A11: AM HARD opens covered | B11: Required 3:45 posts filled or UNFILLED
A12: AM full ops complete | B12: Right side has names except Not Staffed
A13: PM handoff correct | B13: 5:45 full-ops → 2:00; 3:45 stay → 12:15
A14: No double-book same period | B14: See duplicate flags below
A15: Client matches playbooks | B15: Client names = playbook names
A16: Surveys switch works | B16: Control Center B4/B5
... A18: Print PM width OK | B18: Print Preview fit width 1 page
A20: LIVE COUNTS
A21: Schedule Date | B21: ='Control Center'!B3
A22: AM Eligible | B22: =COUNTIF('AM Pool'!A5:A200,"Y")
A23: PM Eligible | B23: =COUNTIF('PM Pool'!A5:A200,"Y")
A24: AM Surveys | B24: ='Control Center'!B4
A25: PM Surveys | B25: ='Control Center'!B5
A27: DUPLICATE CHECK (snapshot)
A28: AM multi-position | B28: Khadijah Van Holten: ['IHOP (1)', 'Front Entrance (#1)']; Maryse Camille: ['Front Entrance (#2)', 'Checkpoint – Inside (#1)']; Larry Fuller: ['We Juice It (1)', 'ADA Entrance (1)']; Natasha Carbon: ['KIA (1)', 'North Divesting (#1)']; Kimberly Morrison: ['Hallway Pre-check Overflow (1)', 'Checkpoint – Inside (1)']; Jessika Williams: ['South Restroom (1)', 'Checkpoint – Inside (1)']
A29: PM multi-position | B29: None — OK
A31: SMOKE-TEST DATES
A32: Scenario | B32: Date tested | C32: AM pool | D32: PM pool | E32: Issues | F32: Pass Y/N
A33: Normal weekday
A34: Heavy absences day
A35: Surveys OFF day

Sheet AM Pool
A1: AM AVAILABLE POOL
A2: Filter column A (AM Eligible?) = Y to see only people available for AM assignment today. Names update when Schedule Date changes (Ctrl+Alt+F5).
A3: Compatible with all Excel versions and LibreOffice. Use AutoFilter on row 4.
A4: AM Eligible? | B4: Employee Name | C4: Shift | D4: Lead | E4: Mentor | F4: Trainee Y/N | G4: Main Inside | H4: Info Desk | I4: Survey | J4: Divest | K4: Mobility Restrict | L4: Assignment Rule | M4: Fixed Position | N4: 3:45 Opening Pos | O4: After 5:45 Pos | P4: Available Today? | R4: Eligible Count: | S4: =COUNTIF(A5:A163,"Y")
A5: =IF('Employee Master'!B2="","",IF(AND('Employee Master'!AD2="Y",OR('Employee Master'!C2="3:45 AM",'Employee Master'!C2="5:45 AM"),'Employee Master'!E2="N"),"Y","N")) | B5: =IF('Employee Master'!B2="","",'Employee Master'!B2) | C5: =IF('Employee Master'!B2="","",'Employee Master'!C2) | D5: =IF('Employee Master'!B2="","",'Employee Master'!E2) | E5: =IF('Employee Master'!B2="","",'Employee Master'!F2) | F5: =IF('Employee Master'!B2="","",'Employee Master'!P2) | G5: =IF('Employee Master'!B2="","",'Employee Master'!J2) | H5: =IF('Employee Master'!B2="","",'Employee Master'!I2) | I5: =IF('Employee Master'!B2="","",'Employee Master'!K2) | J5: =IF('Employee Master'!B2="","",'Employee Master'!L2) | K5: =IF('Employee Master'!B2="","",'Employee Master'!T2) | L5: =IF('Employee Master'!B2="","",'Employee Master'!M2) | M5: =IF('Employee Master'!B2="","",'Employee Master'!N2) | N5: =IF('Employee Master'!B2="","",'Employee Master'!R2) | O5: =IF('Employee Master'!B2="","",'Employee Master'!S2) | P5: =IF('Employee Master'!B2="","",'Employee Master'!AD2)
A6: =IF('Employee Master'!B3="","",IF(AND('Employee Master'!AD3="Y",OR('Employee Master'!C3="3:45 AM",'Employee Master'!C3="5:45 AM"),'Employee Master'!E3="N"),"Y","N")) | B6: =IF('Employee Master'!B3="","",'Employee Master'!B3) | C6: =IF('Employee Master'!B3="","",'Employee Master'!C3) | D6: =IF('Employee Master'!B3="","",'Employee Master'!E3) | E6: =IF('Employee Master'!B3="","",'Employee Master'!F3) | F6: =IF('Employee Master'!B3="","",'Employee Master'!P3) | G6: =IF('Employee Master'!B3="","",'Employee Master'!J3) | H6: =IF('Employee Master'!B3="","",'Employee Master'!I3) | I6: =IF('Employee Master'!B3="","",'Employee Master'!K3) | J6: =IF('Employee Master'!B3="","",'Employee Master'!L3) | K6: =IF('Employee Master'!B3="","",'Employee Master'!T3) | L6: =IF('Employee Master'!B3="","",'Employee Master'!M3) | M6: =IF('Employee Master'!B3="","",'Employee Master'!N3) | N6: =IF('Employee Master'!B3="","",'Employee Master'!R3) | O6: =IF('Employee Master'!B3="","",'Employee Master'!S3) | P6: =IF('Employee Master'!B3="","",'Employee Master'!AD3)
A7: =IF('Employee Master'!B4="","",IF(AND('Employee Master'!AD4="Y",OR('Employee Master'!C4="3:45 AM",'Employee Master'!C4="5:45 AM"),'Employee Master'!E4="N"),"Y","N")) | B7: =IF('Employee Master'!B4="","",'Employee Master'!B4) | C7: =IF('Employee Master'!B4="","",'Employee Master'!C4) | D7: =IF('Employee Master'!B4="","",'Employee Master'!E4) | E7: =IF('Employee Master'!B4="","",'Employee Master'!F4) | F7: =IF('Employee Master'!B4="","",'Employee Master'!P4) | G7: =IF('Employee Master'!B4="","",'Employee Master'!J4) | H7: =IF('Employee Master'!B4="","",'Employee Master'!I4) | I7: =IF('Employee Master'!B4="","",'Employee Master'!K4) | J7: =IF('Employee Master'!B4="","",'Employee Master'!L4) | K7: =IF('Employee Master'!B4="","",'Employee Master'!T4) | L7: =IF('Employee Master'!B4="","",'Employee Master'!M4) | M7: =IF('Employee Master'!B4="","",'Employee Master'!N4) | N7: =IF('Employee Master'!B4="","",'Employee Master'!R4) | O7: =IF('Employee Master'!B4="","",'Employee Master'!S4) | P7: =IF('Employee Master'!B4="","",'Employee Master'!AD4)
A8: =IF('Employee Master'!B5="","",IF(AND('Employee Master'!AD5="Y",OR('Employee Master'!C5="3:45 AM",'Employee Master'!C5="5:45 AM"),'Employee Master'!E5="N"),"Y","N")) | B8: =IF('Employee Master'!B5="","",'Employee Master'!B5) | C8: =IF('Employee Master'!B5="","",'Employee Master'!C5) | D8: =IF('Employee Master'!B5="","",'Employee Master'!E5) | E8: =IF('Employee Master'!B5="","",'Employee Master'!F5) | F8: =IF('Employee Master'!B5="","",'Employee Master'!P5) | G8: =IF('Employee Master'!B5="","",'Employee Master'!J5) | H8: =IF('Employee Master'!B5="","",'Employee Master'!I5) | I8: =IF('Employee Master'!B5="","",'Employee Master'!K5) | J8: =IF('Employee Master'!B5="","",'Employee Master'!L5) | K8: =IF('Employee Master'!B5="","",'Employee Master'!T5) | L8: =IF('Employee Master'!B5="","",'Employee Master'!M5) | M8: =IF('Employee Master'!B5="","",'Employee Master'!N5) | N8: =IF('Employee Master'!B5="","",'Employee Master'!R5) | O8: =IF('Employee Master'!B5="","",'Employee Master'!S5) | P8: =IF('Employee Master'!B5="","",'Employee Master'!AD5)
A9: =IF('Employee Master'!B6="","",IF(AND('Employee Master'!AD6="Y",OR('Employee Master'!C6="3:45 AM",'Employee Master'!C6="5:45 AM"),'Employee Master'!E6="N"),"Y","N")) | B9: =IF('Employee Master'!B6="","",'Employee Master'!B6) | C9: =IF('Employee Master'!B6="","",'Employee Master'!C6) | D9: =IF('Employee Master'!B6="","",'Employee Master'!E6) | E9: =IF('Employee Master'!B6="","",'Employee Master'!F6) | F9: =IF('Employee Master'!B6="","",'Employee Master'!P6) | G9: =IF('Employee Master'!B6="","",'Employee Master'!J6) | H9: =IF('Employee Master'!B6="","",'Employee Master'!I6) | I9: =IF('Employee Master'!B6="","",'Employee Master'!K6) | J9: =IF('Employee Master'!B6="","",'Employee Master'!L6) | K9: =IF('Employee Master'!B6="","",'Employee Master'!T6) | L9: =IF('Employee Master'!B6="","",'Employee Master'!M6) | M9: =IF('Employee Master'!B6="","",'Employee Master'!N6) | N9: =IF('Employee Master'!B6="","",'Employee Master'!R6) | O9: =IF('Employee Master'!B6="","",'Employee Master'!S6) | P9: =IF('Employee Master'!B6="","",'Employee Master'!AD6)
A10: =IF('Employee Master'!B7="","",IF(AND('Employee Master'!AD7="Y",OR('Employee Master'!C7="3:45 AM",'Employee Master'!C7="5:45 AM"),'Employee Master'!E7="N"),"Y","N")) | B10: =IF('Employee Master'!B7="","",'Employee Master'!B7) | C10: =IF('Employee Master'!B7="","",'Employee Master'!C7) | D10: =IF('Employee Master'!B7="","",'Employee Master'!E7) | E10: =IF('Employee Master'!B7="","",'Employee Master'!F7) | F10: =IF('Employee Master'!B7="","",'Employee Master'!P7) | G10: =IF('Employee Master'!B7="","",'Employee Master'!J7) | H10: =IF('Employee Master'!B7="","",'Employee Master'!I7) | I10: =IF('Employee Master'!B7="","",'Employee Master'!K7) | J10: =IF('Employee Master'!B7="","",'Employee Master'!L7) | K10: =IF('Employee Master'!B7="","",'Employee Master'!T7) | L10: =IF('Employee Master'!B7="","",'Employee Master'!M7) | M10: =IF('Employee Master'!B7="","",'Employee Master'!N7) | N10: =IF('Employee Master'!B7="","",'Employee Master'!R7) | O10: =IF('Employee Master'!B7="","",'Employee Master'!S7) | P10: =IF('Employee Master'!B7="","",'Employee Master'!AD7)
A11: =IF('Employee Master'!B8="","",IF(AND('Employee Master'!AD8="Y",OR('Employee Master'!C8="3:45 AM",'Employee Master'!C8="5:45 AM"),'Employee Master'!E8="N"),"Y","N")) | B11: =IF('Employee Master'!B8="","",'Employee Master'!B8) | C11: =IF('Employee Master'!B8="","",'Employee Master'!C8) | D11: =IF('Employee Master'!B8="","",'Employee Master'!E8) | E11: =IF('Employee Master'!B8="","",'Employee Master'!F8) | F11: =IF('Employee Master'!B8="","",'Employee Master'!P8) | G11: =IF('Employee Master'!B8="","",'Employee Master'!J8) | H11: =IF('Employee Master'!B8="","",'Employee Master'!I8) | I11: =IF('Employee Master'!B8="","",'Employee Master'!K8) | J11: =IF('Employee Master'!B8="","",'Employee Master'!L8) | K11: =IF('Employee Master'!B8="","",'Employee Master'!T8) | L11: =IF('Employee Master'!B8="","",'Employee Master'!M8) | M11: =IF('Employee Master'!B8="","",'Employee Master'!N8) | N11: =IF('Employee Master'!B8="","",'Employee Master'!R8) | O11: =IF('Employee Master'!B8="","",'Employee Master'!S8) | P11: =IF('Employee Master'!B8="","",'Employee Master'!AD8)
A12: =IF('Employee Master'!B9="","",IF(AND('Employee Master'!AD9="Y",OR('Employee Master'!C9="3:45 AM",'Employee Master'!C9="5:45 AM"),'Employee Master'!E9="N"),"Y","N")) | B12: =IF('Employee Master'!B9="","",'Employee Master'!B9) | C12: =IF('Employee Master'!B9="","",'Employee Master'!C9) | D12: =IF('Employee Master'!B9="","",'Employee Master'!E9) | E12: =IF('Employee Master'!B9="","",'Employee Master'!F9) | F12: =IF('Employee Master'!B9="","",'Employee Master'!P9) | G12: =IF('Employee Master'!B9="","",'Employee Master'!J9) | H12: =IF('Employee Master'!B9="","",'Employee Master'!I9) | I12: =IF('Employee Master'!B9="","",'Employee Master'!K9) | J12: =IF('Employee Master'!B9="","",'Employee Master'!L9) | K12: =IF('Employee Master'!B9="","",'Employee Master'!T9) | L12: =IF('Employee Master'!B9="","",'Employee Master'!M9) | M12: =IF('Employee Master'!B9="","",'Employee Master'!N9) | N12: =IF('Employee Master'!B9="","",'Employee Master'!R9) | O12: =IF('Employee Master'!B9="","",'Employee Master'!S9) | P12: =IF('Employee Master'!B9="","",'Employee Master'!AD9)
A13: =IF('Employee Master'!B10="","",IF(AND('Employee Master'!AD10="Y",OR('Employee Master'!C10="3:45 AM",'Employee Master'!C10="5:45 AM"),'Employee Master'!E10="N"),"Y","N")) | B13: =IF('Employee Master'!B10="","",'Employee Master'!B10) | C13: =IF('Employee Master'!B10="","",'Employee Master'!C10) | D13: =IF('Employee Master'!B10="","",'Employee Master'!E10) | E13: =IF('Employee Master'!B10="","",'Employee Master'!F10) | F13: =IF('Employee Master'!B10="","",'Employee Master'!P10) | G13: =IF('Employee Master'!B10="","",'Employee Master'!J10) | H13: =IF('Employee Master'!B10="","",'Employee Master'!I10) | I13: =IF('Employee Master'!B10="","",'Employee Master'!K10) | J13: =IF('Employee Master'!B10="","",'Employee Master'!L10) | K13: =IF('Employee Master'!B10="","",'Employee Master'!T10) | L13: =IF('Employee Master'!B10="","",'Employee Master'!M10) | M13: =IF('Employee Master'!B10="","",'Employee Master'!N10) | N13: =IF('Employee Master'!B10="","",'Employee Master'!R10) | O13: =IF('Employee Master'!B10="","",'Employee Master'!S10) | P13: =IF('Employee Master'!B10="","",'Employee Master'!AD10)
A14: =IF('Employee Master'!B11="","",IF(AND('Employee Master'!AD11="Y",OR('Employee Master'!C11="3:45 AM",'Employee Master'!C11="5:45 AM"),'Employee Master'!E11="N"),"Y","N")) | B14: =IF('Employee Master'!B11="","",'Employee Master'!B11) | C14: =IF('Employee Master'!B11="","",'Employee Master'!C11) | D14: =IF('Employee Master'!B11="","",'Employee Master'!E11) | E14: =IF('Employee Master'!B11="","",'Employee Master'!F11) | F14: =IF('Employee Master'!B11="","",'Employee Master'!P11) | G14: =IF('Employee Master'!B11="","",'Employee Master'!J11) | H14: =IF('Employee Master'!B11="","",'Employee Master'!I11) | I14: =IF('Employee Master'!B11="","",'Employee Master'!K11) | J14: =IF('Employee Master'!B11="","",'Employee Master'!L11) | K14: =IF('Employee Master'!B11="","",'Employee Master'!T11) | L14: =IF('Employee Master'!B11="","",'Employee Master'!M11) | M14: =IF('Employee Master'!B11="","",'Employee Master'!N11) | N14: =IF('Employee Master'!B11="","",'Employee Master'!R11) | O14: =IF('Employee Master'!B11="","",'Employee Master'!S11) | P14: =IF('Employee Master'!B11="","",'Employee Master'!AD11)
A15: =IF('Employee Master'!B12="","",IF(AND('Employee Master'!AD12="Y",OR('Employee Master'!C12="3:45 AM",'Employee Master'!C12="5:45 AM"),'Employee Master'!E12="N"),"Y","N")) | B15: =IF('Employee Master'!B12="","",'Employee Master'!B12) | C15: =IF('Employee Master'!B12="","",'Employee Master'!C12) | D15: =IF('Employee Master'!B12="","",'Employee Master'!E12) | E15: =IF('Employee Master'!B12="","",'Employee Master'!F12) | F15: =IF('Employee Master'!B12="","",'Employee Master'!P12) | G15: =IF('Employee Master'!B12="","",'Employee Master'!J12) | H15: =IF('Employee Master'!B12="","",'Employee Master'!I12) | I15: =IF('Employee Master'!B12="","",'Employee Master'!K12) | J15: =IF('Employee Master'!B12="","",'Employee Master'!L12) | K15: =IF('Employee Master'!B12="","",'Employee Master'!T12) | L15: =IF('Employee Master'!B12="","",'Employee Master'!M12) | M15: =IF('Employee Master'!B12="","",'Employee Master'!N12) | N15: =IF('Employee Master'!B12="","",'Employee Master'!R12) | O15: =IF('Employee Master'!B12="","",'Employee Master'!S12) | P15: =IF('Employee Master'!B12="","",'Employee Master'!AD12)
A16: =IF('Employee Master'!B13="","",IF(AND('Employee Master'!AD13="Y",OR('Employee Master'!C13="3:45 AM",'Employee Master'!C13="5:45 AM"),'Employee Master'!E13="N"),"Y","N")) | B16: =IF('Employee Master'!B13="","",'Employee Master'!B13) | C16: =IF('Employee Master'!B13="","",'Employee Master'!C13) | D16: =IF('Employee Master'!B13="","",'Employee Master'!E13) | E16: =IF('Employee Master'!B13="","",'Employee Master'!F13) | F16: =IF('Employee Master'!B13="","",'Employee Master'!P13) | G16: =IF('Employee Master'!B13="","",'Employee Master'!J13) | H16: =IF('Employee Master'!B13="","",'Employee Master'!I13) | I16: =IF('Employee Master'!B13="","",'Employee Master'!K13) | J16: =IF('Employee Master'!B13="","",'Employee Master'!L13) | K16: =IF('Employee Master'!B13="","",'Employee Master'!T13) | L16: =IF('Employee Master'!B13="","",'Employee Master'!M13) | M16: =IF('Employee Master'!B13="","",'Employee Master'!N13) | N16: =IF('Employee Master'!B13="","",'Employee Master'!R13) | O16: =IF('Employee Master'!B13="","",'Employee Master'!S13) | P16: =IF('Employee Master'!B13="","",'Employee Master'!AD13)
... A163: =IF('Employee Master'!B160="","",IF(AND('Employee Master'!AD160="Y",OR('Employee Master'!C160="3:45 AM",'Employee Master'!C160="5:45 AM"),'Employee Master'!E160="N"),"Y","N")) | B163: =IF('Employee Master'!B160="","",'Employee Master'!B160) | C163: =IF('Employee Master'!B160="","",'Employee Master'!C160) | D163: =IF('Employee Master'!B160="","",'Employee Master'!E160) | E163: =IF('Employee Master'!B160="","",'Employee Master'!F160) | F163: =IF('Employee Master'!B160="","",'Employee Master'!P160) | G163: =IF('Employee Master'!B160="","",'Employee Master'!J160) | H163: =IF('Employee Master'!B160="","",'Employee Master'!I160) | I163: =IF('Employee Master'!B160="","",'Employee Master'!K160) | J163: =IF('Employee Master'!B160="","",'Employee Master'!L160) | K163: =IF('Employee Master'!B160="","",'Employee Master'!T160) | L163: =IF('Employee Master'!B160="","",'Employee Master'!M160) | M163: =IF('Employee Master'!B160="","",'Employee Master'!N160) | N163: =IF('Employee Master'!B160="","",'Employee Master'!R160) | O163: =IF('Employee Master'!B160="","",'Employee Master'!S160) | P163: =IF('Employee Master'!B160="","",'Employee Master'!AD160)

Sheet PM Pool
A1: PM AVAILABLE POOL
A2: Filter column A (PM Eligible?) = Y. Names update when Schedule Date changes (Ctrl+Alt+F5). Lead=N, Available Today, shift 12:15 or 2:00.
A4: PM Eligible? | B4: Employee Name | C4: Shift | D4: Lead | E4: Mentor | F4: Trainee Y/N | G4: Main Inside | H4: Info Desk | I4: Survey | J4: Divest | K4: Mobility Restrict | L4: Assignment Rule | M4: Fixed Position | N4: Lunch Preference | O4: Available Today? | P4: Eligible Count: | Q4: =COUNTIF(A5:A169,"Y")
A5: =IF('Employee Master'!B2="","",IF(AND('Employee Master'!AD2="Y",OR('Employee Master'!C2="12:15 PM",'Employee Master'!C2="2:00 PM"),'Employee Master'!E2="N"),"Y","N")) | B5: =IF('Employee Master'!B2="","",'Employee Master'!B2) | C5: =IF('Employee Master'!B2="","",'Employee Master'!C2) | D5: =IF('Employee Master'!B2="","",'Employee Master'!E2) | E5: =IF('Employee Master'!B2="","",'Employee Master'!F2) | F5: =IF('Employee Master'!B2="","",'Employee Master'!P2) | G5: =IF('Employee Master'!B2="","",'Employee Master'!J2) | H5: =IF('Employee Master'!B2="","",'Employee Master'!I2) | I5: =IF('Employee Master'!B2="","",'Employee Master'!K2) | J5: =IF('Employee Master'!B2="","",'Employee Master'!L2) | K5: =IF('Employee Master'!B2="","",'Employee Master'!T2) | L5: =IF('Employee Master'!B2="","",'Employee Master'!M2) | M5: =IF('Employee Master'!B2="","",'Employee Master'!N2) | N5: =IF('Employee Master'!B2="","",'Employee Master'!H2) | O5: =IF('Employee Master'!B2="","",'Employee Master'!AD2)
A6: =IF('Employee Master'!B3="","",IF(AND('Employee Master'!AD3="Y",OR('Employee Master'!C3="12:15 PM",'Employee Master'!C3="2:00 PM"),'Employee Master'!E3="N"),"Y","N")) | B6: =IF('Employee Master'!B3="","",'Employee Master'!B3) | C6: =IF('Employee Master'!B3="","",'Employee Master'!C3) | D6: =IF('Employee Master'!B3="","",'Employee Master'!E3) | E6: =IF('Employee Master'!B3="","",'Employee Master'!F3) | F6: =IF('Employee Master'!B3="","",'Employee Master'!P3) | G6: =IF('Employee Master'!B3="","",'Employee Master'!J3) | H6: =IF('Employee Master'!B3="","",'Employee Master'!I3) | I6: =IF('Employee Master'!B3="","",'Employee Master'!K3) | J6: =IF('Employee Master'!B3="","",'Employee Master'!L3) | K6: =IF('Employee Master'!B3="","",'Employee Master'!T3) | L6: =IF('Employee Master'!B3="","",'Employee Master'!M3) | M6: =IF('Employee Master'!B3="","",'Employee Master'!N3) | N6: =IF('Employee Master'!B3="","",'Employee Master'!H3) | O6: =IF('Employee Master'!B3="","",'Employee Master'!AD3)
A7: =IF('Employee Master'!B4="","",IF(AND('Employee Master'!AD4="Y",OR('Employee Master'!C4="12:15 PM",'Employee Master'!C4="2:00 PM"),'Employee Master'!E4="N"),"Y","N")) | B7: =IF('Employee Master'!B4="","",'Employee Master'!B4) | C7: =IF('Employee Master'!B4="","",'Employee Master'!C4) | D7: =IF('Employee Master'!B4="","",'Employee Master'!E4) | E7: =IF('Employee Master'!B4="","",'Employee Master'!F4) | F7: =IF('Employee Master'!B4="","",'Employee Master'!P4) | G7: =IF('Employee Master'!B4="","",'Employee Master'!J4) | H7: =IF('Employee Master'!B4="","",'Employee Master'!I4) | I7: =IF('Employee Master'!B4="","",'Employee Master'!K4) | J7: =IF('Employee Master'!B4="","",'Employee Master'!L4) | K7: =IF('Employee Master'!B4="","",'Employee Master'!T4) | L7: =IF('Employee Master'!B4="","",'Employee Master'!M4) | M7: =IF('Employee Master'!B4="","",'Employee Master'!N4) | N7: =IF('Employee Master'!B4="","",'Employee Master'!H4) | O7: =IF('Employee Master'!B4="","",'Employee Master'!AD4)
A8: =IF('Employee Master'!B5="","",IF(AND('Employee Master'!AD5="Y",OR('Employee Master'!C5="12:15 PM",'Employee Master'!C5="2:00 PM"),'Employee Master'!E5="N"),"Y","N")) | B8: =IF('Employee Master'!B5="","",'Employee Master'!B5) | C8: =IF('Employee Master'!B5="","",'Employee Master'!C5) | D8: =IF('Employee Master'!B5="","",'Employee Master'!E5) | E8: =IF('Employee Master'!B5="","",'Employee Master'!F5) | F8: =IF('Employee Master'!B5="","",'Employee Master'!P5) | G8: =IF('Employee Master'!B5="","",'Employee Master'!J5) | H8: =IF('Employee Master'!B5="","",'Employee Master'!I5) | I8: =IF('Employee Master'!B5="","",'Employee Master'!K5) | J8: =IF('Employee Master'!B5="","",'Employee Master'!L5) | K8: =IF('Employee Master'!B5="","",'Employee Master'!T5) | L8: =IF('Employee Master'!B5="","",'Employee Master'!M5) | M8: =IF('Employee Master'!B5="","",'Employee Master'!N5) | N8: =IF('Employee Master'!B5="","",'Employee Master'!H5) | O8: =IF('Employee Master'!B5="","",'Employee Master'!AD5)
A9: =IF('Employee Master'!B6="","",IF(AND('Employee Master'!AD6="Y",OR('Employee Master'!C6="12:15 PM",'Employee Master'!C6="2:00 PM"),'Employee Master'!E6="N"),"Y","N")) | B9: =IF('Employee Master'!B6="","",'Employee Master'!B6) | C9: =IF('Employee Master'!B6="","",'Employee Master'!C6) | D9: =IF('Employee Master'!B6="","",'Employee Master'!E6) | E9: =IF('Employee Master'!B6="","",'Employee Master'!F6) | F9: =IF('Employee Master'!B6="","",'Employee Master'!P6) | G9: =IF('Employee Master'!B6="","",'Employee Master'!J6) | H9: =IF('Employee Master'!B6="","",'Employee Master'!I6) | I9: =IF('Employee Master'!B6="","",'Employee Master'!K6) | J9: =IF('Employee Master'!B6="","",'Employee Master'!L6) | K9: =IF('Employee Master'!B6="","",'Employee Master'!T6) | L9: =IF('Employee Master'!B6="","",'Employee Master'!M6) | M9: =IF('Employee Master'!B6="","",'Employee Master'!N6) | N9: =IF('Employee Master'!B6="","",'Employee Master'!H6) | O9: =IF('Employee Master'!B6="","",'Employee Master'!AD6)
A10: =IF('Employee Master'!B7="","",IF(AND('Employee Master'!AD7="Y",OR('Employee Master'!C7="12:15 PM",'Employee Master'!C7="2:00 PM"),'Employee Master'!E7="N"),"Y","N")) | B10: =IF('Employee Master'!B7="","",'Employee Master'!B7) | C10: =IF('Employee Master'!B7="","",'Employee Master'!C7) | D10: =IF('Employee Master'!B7="","",'Employee Master'!E7) | E10: =IF('Employee Master'!B7="","",'Employee Master'!F7) | F10: =IF('Employee Master'!B7="","",'Employee Master'!P7) | G10: =IF('Employee Master'!B7="","",'Employee Master'!J7) | H10: =IF('Employee Master'!B7="","",'Employee Master'!I7) | I10: =IF('Employee Master'!B7="","",'Employee Master'!K7) | J10: =IF('Employee Master'!B7="","",'Employee Master'!L7) | K10: =IF('Employee Master'!B7="","",'Employee Master'!T7) | L10: =IF('Employee Master'!B7="","",'Employee Master'!M7) | M10: =IF('Employee Master'!B7="","",'Employee Master'!N7) | N10: =IF('Employee Master'!B7="","",'Employee Master'!H7) | O10: =IF('Employee Master'!B7="","",'Employee Master'!AD7)
A11: =IF('Employee Master'!B8="","",IF(AND('Employee Master'!AD8="Y",OR('Employee Master'!C8="12:15 PM",'Employee Master'!C8="2:00 PM"),'Employee Master'!E8="N"),"Y","N")) | B11: =IF('Employee Master'!B8="","",'Employee Master'!B8) | C11: =IF('Employee Master'!B8="","",'Employee Master'!C8) | D11: =IF('Employee Master'!B8="","",'Employee Master'!E8) | E11: =IF('Employee Master'!B8="","",'Employee Master'!F8) | F11: =IF('Employee Master'!B8="","",'Employee Master'!P8) | G11: =IF('Employee Master'!B8="","",'Employee Master'!J8) | H11: =IF('Employee Master'!B8="","",'Employee Master'!I8) | I11: =IF('Employee Master'!B8="","",'Employee Master'!K8) | J11: =IF('Employee Master'!B8="","",'Employee Master'!L8) | K11: =IF('Employee Master'!B8="","",'Employee Master'!T8) | L11: =IF('Employee Master'!B8="","",'Employee Master'!M8) | M11: =IF('Employee Master'!B8="","",'Employee Master'!N8) | N11: =IF('Employee Master'!B8="","",'Employee Master'!H8) | O11: =IF('Employee Master'!B8="","",'Employee Master'!AD8)
A12: =IF('Employee Master'!B9="","",IF(AND('Employee Master'!AD9="Y",OR('Employee Master'!C9="12:15 PM",'Employee Master'!C9="2:00 PM"),'Employee Master'!E9="N"),"Y","N")) | B12: =IF('Employee Master'!B9="","",'Employee Master'!B9) | C12: =IF('Employee Master'!B9="","",'Employee Master'!C9) | D12: =IF('Employee Master'!B9="","",'Employee Master'!E9) | E12: =IF('Employee Master'!B9="","",'Employee Master'!F9) | F12: =IF('Employee Master'!B9="","",'Employee Master'!P9) | G12: =IF('Employee Master'!B9="","",'Employee Master'!J9) | H12: =IF('Employee Master'!B9="","",'Employee Master'!I9) | I12: =IF('Employee Master'!B9="","",'Employee Master'!K9) | J12: =IF('Employee Master'!B9="","",'Employee Master'!L9) | K12: =IF('Employee Master'!B9="","",'Employee Master'!T9) | L12: =IF('Employee Master'!B9="","",'Employee Master'!M9) | M12: =IF('Employee Master'!B9="","",'Employee Master'!N9) | N12: =IF('Employee Master'!B9="","",'Employee Master'!H9) | O12: =IF('Employee Master'!B9="","",'Employee Master'!AD9)
A13: =IF('Employee Master'!B10="","",IF(AND('Employee Master'!AD10="Y",OR('Employee Master'!C10="12:15 PM",'Employee Master'!C10="2:00 PM"),'Employee Master'!E10="N"),"Y","N")) | B13: =IF('Employee Master'!B10="","",'Employee Master'!B10) | C13: =IF('Employee Master'!B10="","",'Employee Master'!C10) | D13: =IF('Employee Master'!B10="","",'Employee Master'!E10) | E13: =IF('Employee Master'!B10="","",'Employee Master'!F10) | F13: =IF('Employee Master'!B10="","",'Employee Master'!P10) | G13: =IF('Employee Master'!B10="","",'Employee Master'!J10) | H13: =IF('Employee Master'!B10="","",'Employee Master'!I10) | I13: =IF('Employee Master'!B10="","",'Employee Master'!K10) | J13: =IF('Employee Master'!B10="","",'Employee Master'!L10) | K13: =IF('Employee Master'!B10="","",'Employee Master'!T10) | L13: =IF('Employee Master'!B10="","",'Employee Master'!M10) | M13: =IF('Employee Master'!B10="","",'Employee Master'!N10) | N13: =IF('Employee Master'!B10="","",'Employee Master'!H10) | O13: =IF('Employee Master'!B10="","",'Employee Master'!AD10)
A14: =IF('Employee Master'!B11="","",IF(AND('Employee Master'!AD11="Y",OR('Employee Master'!C11="12:15 PM",'Employee Master'!C11="2:00 PM"),'Employee Master'!E11="N"),"Y","N")) | B14: =IF('Employee Master'!B11="","",'Employee Master'!B11) | C14: =IF('Employee Master'!B11="","",'Employee Master'!C11) | D14: =IF('Employee Master'!B11="","",'Employee Master'!E11) | E14: =IF('Employee Master'!B11="","",'Employee Master'!F11) | F14: =IF('Employee Master'!B11="","",'Employee Master'!P11) | G14: =IF('Employee Master'!B11="","",'Employee Master'!J11) | H14: =IF('Employee Master'!B11="","",'Employee Master'!I11) | I14: =IF('Employee Master'!B11="","",'Employee Master'!K11) | J14: =IF('Employee Master'!B11="","",'Employee Master'!L11) | K14: =IF('Employee Master'!B11="","",'Employee Master'!T11) | L14: =IF('Employee Master'!B11="","",'Employee Master'!M11) | M14: =IF('Employee Master'!B11="","",'Employee Master'!N11) | N14: =IF('Employee Master'!B11="","",'Employee Master'!H11) | O14: =IF('Employee Master'!B11="","",'Employee Master'!AD11)
A15: =IF('Employee Master'!B12="","",IF(AND('Employee Master'!AD12="Y",OR('Employee Master'!C12="12:15 PM",'Employee Master'!C12="2:00 PM"),'Employee Master'!E12="N"),"Y","N")) | B15: =IF('Employee Master'!B12="","",'Employee Master'!B12) | C15: =IF('Employee Master'!B12="","",'Employee Master'!C12) | D15: =IF('Employee Master'!B12="","",'Employee Master'!E12) | E15: =IF('Employee Master'!B12="","",'Employee Master'!F12) | F15: =IF('Employee Master'!B12="","",'Employee Master'!P12) | G15: =IF('Employee Master'!B12="","",'Employee Master'!J12) | H15: =IF('Employee Master'!B12="","",'Employee Master'!I12) | I15: =IF('Employee Master'!B12="","",'Employee Master'!K12) | J15: =IF('Employee Master'!B12="","",'Employee Master'!L12) | K15: =IF('Employee Master'!B12="","",'Employee Master'!T12) | L15: =IF('Employee Master'!B12="","",'Employee Master'!M12) | M15: =IF('Employee Master'!B12="","",'Employee Master'!N12) | N15: =IF('Employee Master'!B12="","",'Employee Master'!H12) | O15: =IF('Employee Master'!B12="","",'Employee Master'!AD12)
A16: =IF('Employee Master'!B13="","",IF(AND('Employee Master'!AD13="Y",OR('Employee Master'!C13="12:15 PM",'Employee Master'!C13="2:00 PM"),'Employee Master'!E13="N"),"Y","N")) | B16: =IF('Employee Master'!B13="","",'Employee Master'!B13) | C16: =IF('Employee Master'!B13="","",'Employee Master'!C13) | D16: =IF('Employee Master'!B13="","",'Employee Master'!E13) | E16: =IF('Employee Master'!B13="","",'Employee Master'!F13) | F16: =IF('Employee Master'!B13="","",'Employee Master'!P13) | G16: =IF('Employee Master'!B13="","",'Employee Master'!J13) | H16: =IF('Employee Master'!B13="","",'Employee Master'!I13) | I16: =IF('Employee Master'!B13="","",'Employee Master'!K13) | J16: =IF('Employee Master'!B13="","",'Employee Master'!L13) | K16: =IF('Employee Master'!B13="","",'Employee Master'!T13) | L16: =IF('Employee Master'!B13="","",'Employee Master'!M13) | M16: =IF('Employee Master'!B13="","",'Employee Master'!N13) | N16: =IF('Employee Master'!B13="","",'Employee Master'!H13) | O16: =IF('Employee Master'!B13="","",'Employee Master'!AD13)
... A169: =IF('Employee Master'!B166="","",IF(AND('Employee Master'!AD166="Y",OR('Employee Master'!C166="12:15 PM",'Employee Master'!C166="2:00 PM"),'Employee Master'!E166="N"),"Y","N")) | B169: =IF('Employee Master'!B166="","",'Employee Master'!B166) | C169: =IF('Employee Master'!B166="","",'Employee Master'!C166) | D169: =IF('Employee Master'!B166="","",'Employee Master'!E166) | E169: =IF('Employee Master'!B166="","",'Employee Master'!F166) | F169: =IF('Employee Master'!B166="","",'Employee Master'!P166) | G169: =IF('Employee Master'!B166="","",'Employee Master'!J166) | H169: =IF('Employee Master'!B166="","",'Employee Master'!I166) | I169: =IF('Employee Master'!B166="","",'Employee Master'!K166) | J169: =IF('Employee Master'!B166="","",'Employee Master'!L166) | K169: =IF('Employee Master'!B166="","",'Employee Master'!T166) | L169: =IF('Employee Master'!B166="","",'Employee Master'!M166) | M169: =IF('Employee Master'!B166="","",'Employee Master'!N166) | N169: =IF('Employee Master'!B166="","",'Employee Master'!H166) | O169: =IF('Employee Master'!B166="","",'Employee Master'!AD166)

Sheet AM Eligible Names
A1: Eligible AM Names (for dropdowns)
A2: Names as of current Schedule Date (49 eligible). Re-run Phase 2 refresh or filter AM Pool after changing date.
A3: PRIMARY METHOD: Go to AM Pool sheet → filter column A = Y → copy names into Playbook.
A4: Name
A5: Adeyeye Opaaje
A6: Ahamed John
A7: Aleah Mckinnon
A8: Allen Suggs
A9: Anariah Daniel
A10: Ashia Norman
A11: Benjamin Crosby
A12: Brian Lee
... A53: George Whitehead

Sheet PM Eligible Names
A1: Eligible PM Names (for dropdowns)
A2: 41 eligible. Oumou Sane off Mon/Tue — not in pool on Mondays.
A3: Name
A4: Aaliyah Snider
A5: Agnes Bammannage
A6: Akuugo Nduaguba
A7: Alyssa Prince
A8: Amadou Diallo
A9: Ashley Lazenby
A10: Bousso Dioum
A11: Braheem Wooden
A12: Brittney Quave
... A44: Zinash Shiferaw

Sheet Approved Absences
A1: Employee Name | B1: Start Date | C1: End Date | D1: Reason

Sheet Employee Master
A1: Employee ID | B1: Employee Name | C1: Shift | D1: Days Off | E1: Lead | F1: Mentor | G1: Active | H1: Lunch Preference | I1: Information Desk | J1: Main Inside | K1: Survey | L1: Divest | M1: Assignment Rule | N1: Fixed All-Shift Position | O1: Day-Specific Restrictions | P1: Trainee Y/N | Q1: Assigned Mentor | R1: 3:45 Opening Position | S1: After 5:45 Position | T1: Mobility Restriction Y/N | U1: Scheduled Today? | V1: AM Regular Pool? | W1: PM Regular Pool? | X1: Training Start Date | Y1: Completion Approved? | Z1: Completion Date | AA1: Training Notes | AB1: Training Status | AC1: v3 Approved Absence? | AD1: v3 Available? | AE1: Rank_AM345_Gen | AF1: Rank_AM545_Gen | AG1: Rank_Div345 | AH1: Rank_Div545 | AI1: Rank_Survey_AM | AJ1: Rank_Main345 | AK1: Rank_Info_AM | AL1: Rank_PM1215 | AM1: Rank_PM200 | AN1: Rank_Survey_PM | AO1: Rank_DivPM1215 | AP1: Rank_DivPM200
A2: EMP-0001 | B2: Aaliyah Snider | C2: 2:00 PM | D2: Wed, Thu | E2: N | F2: N | G2: Y | H2: None | I2: Y | J2: Y | K2: N | L2: Y | M2: Standard | P2: N | T2: N | U2: =IF($B2="","",IF(AND($G2="Y",ISERROR(SEARCH(TEXT('Control Center'!$B$3,"ddd"),TRIM($D2)))),"Y","N")) | V2: =IF($B2="","",IF(AND($U2="Y",OR($C2="3:45 AM",$C2="5:45 AM"),OR('Control Center'!$B$4="N",$K2<>"Y")),"Y","N")) | W2: =IF($B2="","",IF(AND($U2="Y",OR($C2="12:15 PM",$C2="2:00 PM"),OR('Control Center'!$B$5="N",$K2<>"Y")),"Y","N")) | AB2: =IF($B2="","",IF($P2="Y",IF($Y2="Y","Completed","In Progress"),"")) | AC2: =IF($B2="","",IF(COUNTIFS('Approved Absences'!$A$2:$A$200,$B2,'Approved Absences'!$B$2:$B$200,"<="&INT('Control Center'!$B$3),'Approved Absences'!$C$2:$C$200,">="&INT('Control Center'!$B$3))>0,"Y","N")) | AD2: =IF($B2="","",IF(AND($G2="Y",$AC2<>"Y",ISERROR(SEARCH(TEXT('Control Center'!$B$3,"ddd"),TRIM($D2)))),"Y","N")) | AE2: =IF(AND(AD2="Y",C2="3:45 AM",E2="N",K2<>"Y"),COUNTIFS($AD$2:AD2,"Y",$C$2:C2,"3:45 AM",$E$2:E2,"N",$K$2:K2,"<>Y"),"") | AF2: =IF(AND(AD2="Y",C2="5:45 AM",E2="N",K2<>"Y"),COUNTIFS($AD$2:AD2,"Y",$C$2:C2,"5:45 AM",$E$2:E2,"N",$K$2:K2,"<>Y"),"") | AG2: =IF(AND(AD2="Y",C2="3:45 AM",E2="N",L2="Y",K2<>"Y"),COUNTIFS($AD$2:AD2,"Y",$C$2:C2,"3:45 AM",$E$2:E2,"N",$L$2:L2,"Y",$K$2:K2,"<>Y"),"") | AH2: =IF(AND(AD2="Y",C2="5:45 AM",E2="N",L2="Y",K2<>"Y"),COUNTIFS($AD$2:AD2,"Y",$C$2:C2,"5:45 AM",$E$2:E2,"N",$L$2:L2,"Y",$K$2:K2,"<>Y"),"") | AI2: =IF(AND(AD2="Y",E2="N",K2="Y",OR(C2="3:45 AM",C2="5:45 AM")),SUMPRODUCT(($AD$2:AD2="Y")*($E$2:E2="N")*($K$2:K2="Y")*(($C$2:C2="3:45 AM")+($C$2:C2="5:45 AM"))), "") | AJ2: =IF(AND(AD2="Y",C2="3:45 AM",E2="N",J2="Y"),COUNTIFS($AD$2:AD2,"Y",$C$2:C2,"3:45 AM",$E$2:E2,"N",$J$2:J2,"Y"),"") | AK2: =IF(AND(AD2="Y",E2="N",I2="Y",OR(C2="3:45 AM",C2="5:45 AM")),SUMPRODUCT(($AD$2:AD2="Y")*($E$2:E2="N")*($I$2:I2="Y")*(($C$2:C2="3:45 AM")+($C$2:C2="5:45 AM"))), "") | AL2: =IF(AND(AD2="Y",C2="12:15 PM",E2="N",K2<>"Y"),COUNTIFS($AD$2:AD2,"Y",$C$2:C2,"12:15 PM",$E$2:E2,"N",$K$2:K2,"<>Y"),"") | AM2: =IF(AND(AD2="Y",C2="2:00 PM",E2="N",K2<>"Y"),COUNTIFS($AD$2:AD2,"Y",$C$2:C2,"2:00 PM",$E$2:E2,"N",$K$2:K2,"<>Y"),"") | AN2: =IF(AND(AD2="Y",E2="N",K2="Y",OR(C2="12:15 PM",C2="2:00 PM")),SUMPRODUCT(($AD$2:AD2="Y")*($E$2:E2="N")*($K$2:K2="Y")*(($C$2:C2="12:15 PM")+($C$2:C2="2:00 PM"))), "") | AO2: =IF(AND(AD2="Y",C2="12:15 PM",E2="N",L2="Y"),COUNTIFS($AD$2:AD2,"Y",$C$2:C2,"12:15 PM",$E$2:E2,"N",$L$2:L2,"Y"),"") | AP2: =IF(AND(AD2="Y",C2="2:00 PM",E2="N",L2="Y"),COUNTIFS($AD$2:AD2,"Y",$C$2:C2,"2:00 PM",$E$2:E2,"N",$L$2:L2,"Y"),"")
