Workbook

Sheet Coverage Rules
A1: RotationOps – Hard Coverage Rules (v1.1)
A2: These rules are mandatory. Any schedule that violates them is invalid. The Tier1 Break Conflict Check sheet will flag violations automatically.
A4: 1. Non-Negotiable Priority
A5: Tier 1 positions must never be left unstaffed for any time interval (including lunch/break windows). Any schedule that leaves a Tier 1 empty is invalid and must be rejected or repaired.
A7: 2. Input Data Required
A8: Employee Master + Daily Workforce (Present status, shift start, qualifications, Lead/Mentor) Position Library (Tier, Priority Relief Required) Position Relationships (ordered relief chain Priority 1–5) Designated lunch windows by shift start Qualification Matrix (especially Divest = Y) 30-day fairness metrics (for Divest ranking only)
A10: 3. Assignment Order (strict)
A11: 1. Assign all Tier 1 positions first (including Divest 46–52). 2. Assign remaining positions by Tier (2 → 3 → 4). 3. Only after every position has a primary assignee, assign lunches. 4. Lower-tier positions may be left temporarily empty only if required to keep a Tier 1 covered.
A13: 4. Divest-Specific Rules (Positions 46–52)
A14: • All seven Divest positions must open with qualified 3:45 AM staff only. • At 5:45 AM a fairness-ranked qualified employee takes over each Divest position. • The original 3:45 opener is released to the takeover employee’s previous position. • Every Divest core employee must receive a dedicated lunch reliever who: – Is Divest-qualified (or meets the relief qualification), – Comes from a lower-tier position, – Has a DIFFERENT lunch wave than the core employee. • No two Divest cores (or a core and its only remaining valid reliever) may share the same lunch wave.
A16: 5. General Lunch Assignment Rules
A17: • Preferred lunch windows come from the designated break times by shift start. • Preference is SECONDARY to coverage. If the preferred window would leave any Tier 1 uncovered, move the lunch to a different valid window. • Before finalizing any lunch, build the live relief graph from Position Relationships + current assignments. • Mutual-exclusion constraint: Two employees may NOT share a lunch wave if they are the only remaining valid coverage for the same Tier 1, or if they sit in each other’s critical relief chain such that simultaneous absence would leave a Tier 1 empty. • After all lunches are assigned, simulate the entire day in 15-minute increments. Any Tier 1 that would be empty → schedule is invalid → force re-assignment of conflicting lunches.
... A26: When ranking 5:45 AM takeover candidates for Divest, use 30-day metrics in this order: 1. Lowest 30-day Divest hours 2. Lowest number of Divest days 3. Lowest consecutive Divest days 4. Lowest number of opening assignments 5. Lowest lunch-relief assignments

Sheet Tier1 Break Conflict Check
A1: Tier 1 Break / Lunch Conflict Detector
A2: This sheet automatically flags any Tier 1 position where the assigned employee and their designated relief share the same lunch window, or where Break Coverage is not COVERED. Red = VIOLATION. Green = OK. Yellow = needs attention (no relief assigned).
A4: Position ID | B4: Area | C4: Position | D4: Tier | E4: Assigned Employee ID | F4: Assigned Employee | G4: Assigned Lunch | H4: Relief Position ID | I4: Relief Employee | J4: Relief Lunch (lookup) | K4: Break Coverage Status | L4: CONFLICT FLAG
A5: 1 | B5: =IFERROR(INDEX('Position Library'!$B$2:$B$53,MATCH(A5,'Position Library'!$A$2:$A$53,0)),"") -> Main Security Checkpoint | C5: =IFERROR(INDEX('Position Library'!$C$2:$C$53,MATCH(A5,'Position Library'!$A$2:$A$53,0)),"") -> Front Entrance | D5: =IFERROR(INDEX('Position Library'!$D$2:$D$53,MATCH(A5,'Position Library'!$A$2:$A$53,0)),"") -> Tier 1 | E5: =IFERROR(INDEX('Daily Schedule'!$F$6:$F$57,MATCH(A5,'Daily Schedule'!$A$6:$A$57,0)),"") -> EMP-0059 | F5: =IFERROR(INDEX('Daily Schedule'!$G$6:$G$57,MATCH(A5,'Daily Schedule'!$A$6:$A$57,0)),"") -> Emonnie Dorsey | G5: =IFERROR(INDEX('Daily Schedule'!$N$6:$N$57,MATCH(A5,'Daily Schedule'!$A$6:$A$57,0)),"") -> 8:00 AM | H5: =IFERROR(INDEX('Daily Schedule'!$O$6:$O$57,MATCH(A5,'Daily Schedule'!$A$6:$A$57,0)),"") -> 9 | I5: =IFERROR(INDEX('Daily Schedule'!$P$6:$P$57,MATCH(A5,'Daily Schedule'!$A$6:$A$57,0)),"") -> EMP-0018 | J5: =IF(I5="","",IFERROR(INDEX('Daily Schedule'!$N$6:$N$57,MATCH(I5,'Daily Schedule'!$G$6:$G$57,0)),IFERROR(INDEX('Daily Schedule'!$N$6:$N$57,MATCH(I5,'Daily Schedule'!$F$6:$F$57,0)),""))) -> 9:00 AM | K5: =IFERROR(INDEX('Daily Schedule'!$Q$6:$Q$57,MATCH(A5,'Daily Schedule'!$A$6:$A$57,0)),"") -> COVERED | L5: =IF(E5="","NO ASSIGNEE",IF(AND(G5<>"",J5<>"",G5=J5),"VIOLATION – SAME LUNCH",IF(OR(K5="RELIEF GAP",K5="POSITION UNFILLED",K5=""),IF(OR(H5="",I5=""),"VIOLATION – NO RELIEF","CHECK MANUALLY"),IF(K5="COVERED","OK","CHECK MANUALLY")))) -> OK
A6: 2 | B6: =IFERROR(INDEX('Position Library'!$B$2:$B$53,MATCH(A6,'Position Library'!$A$2:$A$53,0)),"") -> Main Security Checkpoint | C6: =IFERROR(INDEX('Position Library'!$C$2:$C$53,MATCH(A6,'Position Library'!$A$2:$A$53,0)),"") -> ADA Entrance | D6: =IFERROR(INDEX('Position Library'!$D$2:$D$53,MATCH(A6,'Position Library'!$A$2:$A$53,0)),"") -> Tier 1 | E6: =IFERROR(INDEX('Daily Schedule'!$F$6:$F$57,MATCH(A6,'Daily Schedule'!$A$6:$A$57,0)),"") -> EMP-0067 | F6: =IFERROR(INDEX('Daily Schedule'!$G$6:$G$57,MATCH(A6,'Daily Schedule'!$A$6:$A$57,0)),"") -> Haddyjatou Ndure | G6: =IFERROR(INDEX('Daily Schedule'!$N$6:$N$57,MATCH(A6,'Daily Schedule'!$A$6:$A$57,0)),"") -> 9:00 AM | H6: =IFERROR(INDEX('Daily Schedule'!$O$6:$O$57,MATCH(A6,'Daily Schedule'!$A$6:$A$57,0)),"") | I6: =IFERROR(INDEX('Daily Schedule'!$P$6:$P$57,MATCH(A6,'Daily Schedule'!$A$6:$A$57,0)),"") | J6: =IF(I6="","",IFERROR(INDEX('Daily Schedule'!$N$6:$N$57,MATCH(I6,'Daily Schedule'!$G$6:$G$57,0)),IFERROR(INDEX('Daily Schedule'!$N$6:$N$57,MATCH(I6,'Daily Schedule'!$F$6:$F$57,0)),""))) | K6: =IFERROR(INDEX('Daily Schedule'!$Q$6:$Q$57,MATCH(A6,'Daily Schedule'!$A$6:$A$57,0)),"") -> RELIEF GAP | L6: =IF(E6="","NO ASSIGNEE",IF(AND(G6<>"",J6<>"",G6=J6),"VIOLATION – SAME LUNCH",IF(OR(K6="RELIEF GAP",K6="POSITION UNFILLED",K6=""),IF(OR(H6="",I6=""),"VIOLATION – NO RELIEF","CHECK MANUALLY"),IF(K6="COVERED","OK","CHECK MANUALLY")))) -> VIOLATION – NO RELIEF
A7: 4 | B7: =IFERROR(INDEX('Position Library'!$B$2:$B$53,MATCH(A7,'Position Library'!$A$2:$A$53,0)),"") -> Main Security Checkpoint | C7: =IFERROR(INDEX('Position Library'!$C$2:$C$53,MATCH(A7,'Position Library'!$A$2:$A$53,0)),"") -> Inside Center | D7: =IFERROR(INDEX('Position Library'!$D$2:$D$53,MATCH(A7,'Position Library'!$A$2:$A$53,0)),"") -> Tier 1 | E7: =IFERROR(INDEX('Daily Schedule'!$F$6:$F$57,MATCH(A7,'Daily Schedule'!$A$6:$A$57,0)),"") | F7: =IFERROR(INDEX('Daily Schedule'!$G$6:$G$57,MATCH(A7,'Daily Schedule'!$A$6:$A$57,0)),"") | G7: =IFERROR(INDEX('Daily Schedule'!$N$6:$N$57,MATCH(A7,'Daily Schedule'!$A$6:$A$57,0)),"") | H7: =IFERROR(INDEX('Daily Schedule'!$O$6:$O$57,MATCH(A7,'Daily Schedule'!$A$6:$A$57,0)),"") -> 5 | I7: =IFERROR(INDEX('Daily Schedule'!$P$6:$P$57,MATCH(A7,'Daily Schedule'!$A$6:$A$57,0)),"") -> EMP-0082 | J7: =IF(I7="","",IFERROR(INDEX('Daily Schedule'!$N$6:$N$57,MATCH(I7,'Daily Schedule'!$G$6:$G$57,0)),IFERROR(INDEX('Daily Schedule'!$N$6:$N$57,MATCH(I7,'Daily Schedule'!$F$6:$F$57,0)),""))) -> 8:00 AM | K7: =IFERROR(INDEX('Daily Schedule'!$Q$6:$Q$57,MATCH(A7,'Daily Schedule'!$A$6:$A$57,0)),"") -> POSITION UNFILLED | L7: =IF(E7="","NO ASSIGNEE",IF(AND(G7<>"",J7<>"",G7=J7),"VIOLATION – SAME LUNCH",IF(OR(K7="RELIEF GAP",K7="POSITION UNFILLED",K7=""),IF(OR(H7="",I7=""),"VIOLATION – NO RELIEF","CHECK MANUALLY"),IF(K7="COVERED","OK","CHECK MANUALLY")))) -> NO ASSIGNEE
A8: 5 | B8: =IFERROR(INDEX('Position Library'!$B$2:$B$53,MATCH(A8,'Position Library'!$A$2:$A$53,0)),"") -> Main Security Checkpoint | C8: =IFERROR(INDEX('Position Library'!$C$2:$C$53,MATCH(A8,'Position Library'!$A$2:$A$53,0)),"") -> Lanes 1 - 3 / Pre-Check | D8: =IFERROR(INDEX('Position Library'!$D$2:$D$53,MATCH(A8,'Position Library'!$A$2:$A$53,0)),"") -> Tier 1 | E8: =IFERROR(INDEX('Daily Schedule'!$F$6:$F$57,MATCH(A8,'Daily Schedule'!$A$6:$A$57,0)),"") -> EMP-0082 | F8: =IFERROR(INDEX('Daily Schedule'!$G$6:$G$57,MATCH(A8,'Daily Schedule'!$A$6:$A$57,0)),"") -> Kelon Arnold | G8: =IFERROR(INDEX('Daily Schedule'!$N$6:$N$57,MATCH(A8,'Daily Schedule'!$A$6:$A$57,0)),"") -> 8:00 AM | H8: =IFERROR(INDEX('Daily Schedule'!$O$6:$O$57,MATCH(A8,'Daily Schedule'!$A$6:$A$57,0)),"") -> 3 | I8: =IFERROR(INDEX('Daily Schedule'!$P$6:$P$57,MATCH(A8,'Daily Schedule'!$A$6:$A$57,0)),"") -> EMP-0009 | J8: =IF(I8="","",IFERROR(INDEX('Daily Schedule'!$N$6:$N$57,MATCH(I8,'Daily Schedule'!$G$6:$G$57,0)),IFERROR(INDEX('Daily Schedule'!$N$6:$N$57,MATCH(I8,'Daily Schedule'!$F$6:$F$57,0)),""))) -> 10:00 AM | K8: =IFERROR(INDEX('Daily Schedule'!$Q$6:$Q$57,MATCH(A8,'Daily Schedule'!$A$6:$A$57,0)),"") -> COVERED | L8: =IF(E8="","NO ASSIGNEE",IF(AND(G8<>"",J8<>"",G8=J8),"VIOLATION – SAME LUNCH",IF(OR(K8="RELIEF GAP",K8="POSITION UNFILLED",K8=""),IF(OR(H8="",I8=""),"VIOLATION – NO RELIEF","CHECK MANUALLY"),IF(K8="COVERED","OK","CHECK MANUALLY")))) -> OK
A9: 8 | B9: =IFERROR(INDEX('Position Library'!$B$2:$B$53,MATCH(A9,'Position Library'!$A$2:$A$53,0)),"") -> Main Security Checkpoint | C9: =IFERROR(INDEX('Position Library'!$C$2:$C$53,MATCH(A9,'Position Library'!$A$2:$A$53,0)),"") -> Inside Center | D9: =IFERROR(INDEX('Position Library'!$D$2:$D$53,MATCH(A9,'Position Library'!$A$2:$A$53,0)),"") -> Tier 1 | E9: =IFERROR(INDEX('Daily Schedule'!$F$6:$F$57,MATCH(A9,'Daily Schedule'!$A$6:$A$57,0)),"") | F9: =IFERROR(INDEX('Daily Schedule'!$G$6:$G$57,MATCH(A9,'Daily Schedule'!$A$6:$A$57,0)),"") | G9: =IFERROR(INDEX('Daily Schedule'!$N$6:$N$57,MATCH(A9,'Daily Schedule'!$A$6:$A$57,0)),"") | H9: =IFERROR(INDEX('Daily Schedule'!$O$6:$O$57,MATCH(A9,'Daily Schedule'!$A$6:$A$57,0)),"") -> 3 | I9: =IFERROR(INDEX('Daily Schedule'!$P$6:$P$57,MATCH(A9,'Daily Schedule'!$A$6:$A$57,0)),"") -> EMP-0009 | J9: =IF(I9="","",IFERROR(INDEX('Daily Schedule'!$N$6:$N$57,MATCH(I9,'Daily Schedule'!$G$6:$G$57,0)),IFERROR(INDEX('Daily Schedule'!$N$6:$N$57,MATCH(I9,'Daily Schedule'!$F$6:$F$57,0)),""))) -> 10:00 AM | K9: =IFERROR(INDEX('Daily Schedule'!$Q$6:$Q$57,MATCH(A9,'Daily Schedule'!$A$6:$A$57,0)),"") -> POSITION UNFILLED | L9: =IF(E9="","NO ASSIGNEE",IF(AND(G9<>"",J9<>"",G9=J9),"VIOLATION – SAME LUNCH",IF(OR(K9="RELIEF GAP",K9="POSITION UNFILLED",K9=""),IF(OR(H9="",I9=""),"VIOLATION – NO RELIEF","CHECK MANUALLY"),IF(K9="COVERED","OK","CHECK MANUALLY")))) -> NO ASSIGNEE
A10: 14 | B10: =IFERROR(INDEX('Position Library'!$B$2:$B$53,MATCH(A10,'Position Library'!$A$2:$A$53,0)),"") -> South Security Checkpoint | C10: =IFERROR(INDEX('Position Library'!$C$2:$C$53,MATCH(A10,'Position Library'!$A$2:$A$53,0)),"") -> Checkpoint – Inside | D10: =IFERROR(INDEX('Position Library'!$D$2:$D$53,MATCH(A10,'Position Library'!$A$2:$A$53,0)),"") -> Tier 1 | E10: =IFERROR(INDEX('Daily Schedule'!$F$6:$F$57,MATCH(A10,'Daily Schedule'!$A$6:$A$57,0)),"") -> EMP-0087 | F10: =IFERROR(INDEX('Daily Schedule'!$G$6:$G$57,MATCH(A10,'Daily Schedule'!$A$6:$A$57,0)),"") -> Kimberly Morrison | G10: =IFERROR(INDEX('Daily Schedule'!$N$6:$N$57,MATCH(A10,'Daily Schedule'!$A$6:$A$57,0)),"") -> 8:00 AM | H10: =IFERROR(INDEX('Daily Schedule'!$O$6:$O$57,MATCH(A10,'Daily Schedule'!$A$6:$A$57,0)),"") -> 16 | I10: =IFERROR(INDEX('Daily Schedule'!$P$6:$P$57,MATCH(A10,'Daily Schedule'!$A$6:$A$57,0)),"") -> EMP-0091 | J10: =IF(I10="","",IFERROR(INDEX('Daily Schedule'!$N$6:$N$57,MATCH(I10,'Daily Schedule'!$G$6:$G$57,0)),IFERROR(INDEX('Daily Schedule'!$N$6:$N$57,MATCH(I10,'Daily Schedule'!$F$6:$F$57,0)),""))) -> 9:00 AM | K10: =IFERROR(INDEX('Daily Schedule'!$Q$6:$Q$57,MATCH(A10,'Daily Schedule'!$A$6:$A$57,0)),"") -> COVERED | L10: =IF(E10="","NO ASSIGNEE",IF(AND(G10<>"",J10<>"",G10=J10),"VIOLATION – SAME LUNCH",IF(OR(K10="RELIEF GAP",K10="POSITION UNFILLED",K10=""),IF(OR(H10="",I10=""),"VIOLATION – NO RELIEF","CHECK MANUALLY"),IF(K10="COVERED","OK","CHECK MANUALLY")))) -> OK
A11: 16 | B11: =IFERROR(INDEX('Position Library'!$B$2:$B$53,MATCH(A11,'Position Library'!$A$2:$A$53,0)),"") -> South Security Checkpoint | C11: =IFERROR(INDEX('Position Library'!$C$2:$C$53,MATCH(A11,'Position Library'!$A$2:$A$53,0)),"") -> Checkpoint – Front Entrance | D11: =IFERROR(INDEX('Position Library'!$D$2:$D$53,MATCH(A11,'Position Library'!$A$2:$A$53,0)),"") -> Tier 1 | E11: =IFERROR(INDEX('Daily Schedule'!$F$6:$F$57,MATCH(A11,'Daily Schedule'!$A$6:$A$57,0)),"") -> EMP-0091 | F11: =IFERROR(INDEX('Daily Schedule'!$G$6:$G$57,MATCH(A11,'Daily Schedule'!$A$6:$A$57,0)),"") -> Larry Fuller | G11: =IFERROR(INDEX('Daily Schedule'!$N$6:$N$57,MATCH(A11,'Daily Schedule'!$A$6:$A$57,0)),"") -> 9:00 AM | H11: =IFERROR(INDEX('Daily Schedule'!$O$6:$O$57,MATCH(A11,'Daily Schedule'!$A$6:$A$57,0)),"") -> 17 | I11: =IFERROR(INDEX('Daily Schedule'!$P$6:$P$57,MATCH(A11,'Daily Schedule'!$A$6:$A$57,0)),"") -> EMP-0026 | J11: =IF(I11="","",IFERROR(INDEX('Daily Schedule'!$N$6:$N$57,MATCH(I11,'Daily Schedule'!$G$6:$G$57,0)),IFERROR(INDEX('Daily Schedule'!$N$6:$N$57,MATCH(I11,'Daily Schedule'!$F$6:$F$57,0)),""))) -> 10:00 AM | K11: =IFERROR(INDEX('Daily Schedule'!$Q$6:$Q$57,MATCH(A11,'Daily Schedule'!$A$6:$A$57,0)),"") -> COVERED | L11: =IF(E11="","NO ASSIGNEE",IF(AND(G11<>"",J11<>"",G11=J11),"VIOLATION – SAME LUNCH",IF(OR(K11="RELIEF GAP",K11="POSITION UNFILLED",K11=""),IF(OR(H11="",I11=""),"VIOLATION – NO RELIEF","CHECK MANUALLY"),IF(K11="COVERED","OK","CHECK MANUALLY")))) -> OK
A12: 19 | B12: =IFERROR(INDEX('Position Library'!$B$2:$B$53,MATCH(A12,'Position Library'!$A$2:$A$53,0)),"") -> South Security Checkpoint | C12: =IFERROR(INDEX('Position Library'!$C$2:$C$53,MATCH(A12,'Position Library'!$A$2:$A$53,0)),"") -> South Restroom | D12: =IFERROR(INDEX('Position Library'!$D$2:$D$53,MATCH(A12,'Position Library'!$A$2:$A$53,0)),"") -> Tier 1 | E12: =IFERROR(INDEX('Daily Schedule'!$F$6:$F$57,MATCH(A12,'Daily Schedule'!$A$6:$A$57,0)),"") -> EMP-0094 | F12: =IFERROR(INDEX('Daily Schedule'!$G$6:$G$57,MATCH(A12,'Daily Schedule'!$A$6:$A$57,0)),"") -> Linda Rachel | G12: =IFERROR(INDEX('Daily Schedule'!$N$6:$N$57,MATCH(A12,'Daily Schedule'!$A$6:$A$57,0)),"") -> 8:00 AM | H12: =IFERROR(INDEX('Daily Schedule'!$O$6:$O$57,MATCH(A12,'Daily Schedule'!$A$6:$A$57,0)),"") -> 20 | I12: =IFERROR(INDEX('Daily Schedule'!$P$6:$P$57,MATCH(A12,'Daily Schedule'!$A$6:$A$57,0)),"") -> EMP-0066 | J12: =IF(I12="","",IFERROR(INDEX('Daily Schedule'!$N$6:$N$57,MATCH(I12,'Daily Schedule'!$G$6:$G$57,0)),IFERROR(INDEX('Daily Schedule'!$N$6:$N$57,MATCH(I12,'Daily Schedule'!$F$6:$F$57,0)),""))) -> 10:00 AM | K12: =IFERROR(INDEX('Daily Schedule'!$Q$6:$Q$57,MATCH(A12,'Daily Schedule'!$A$6:$A$57,0)),"") -> COVERED | L12: =IF(E12="","NO ASSIGNEE",IF(AND(G12<>"",J12<>"",G12=J12),"VIOLATION – SAME LUNCH",IF(OR(K12="RELIEF GAP",K12="POSITION UNFILLED",K12=""),IF(OR(H12="",I12=""),"VIOLATION – NO RELIEF","CHECK MANUALLY"),IF(K12="COVERED","OK","CHECK MANUALLY")))) -> OK
A13: 24 | B13: =IFERROR(INDEX('Position Library'!$B$2:$B$53,MATCH(A13,'Position Library'!$A$2:$A$53,0)),"") -> North Security Checkpoint | C13: =IFERROR(INDEX('Position Library'!$C$2:$C$53,MATCH(A13,'Position Library'!$A$2:$A$53,0)),"") -> Checkpoint – Inside | D13: =IFERROR(INDEX('Position Library'!$D$2:$D$53,MATCH(A13,'Position Library'!$A$2:$A$53,0)),"") -> Tier 1 | E13: =IFERROR(INDEX('Daily Schedule'!$F$6:$F$57,MATCH(A13,'Daily Schedule'!$A$6:$A$57,0)),"") -> EMP-0102 | F13: =IFERROR(INDEX('Daily Schedule'!$G$6:$G$57,MATCH(A13,'Daily Schedule'!$A$6:$A$57,0)),"") -> Maryse Camille | G13: =IFERROR(INDEX('Daily Schedule'!$N$6:$N$57,MATCH(A13,'Daily Schedule'!$A$6:$A$57,0)),"") -> 8:00 AM | H13: =IFERROR(INDEX('Daily Schedule'!$O$6:$O$57,MATCH(A13,'Daily Schedule'!$A$6:$A$57,0)),"") -> 29 | I13: =IFERROR(INDEX('Daily Schedule'!$P$6:$P$57,MATCH(A13,'Daily Schedule'!$A$6:$A$57,0)),"") -> EMP-0040 | J13: =IF(I13="","",IFERROR(INDEX('Daily Schedule'!$N$6:$N$57,MATCH(I13,'Daily Schedule'!$G$6:$G$57,0)),IFERROR(INDEX('Daily Schedule'!$N$6:$N$57,MATCH(I13,'Daily Schedule'!$F$6:$F$57,0)),""))) -> 9:00 AM | K13: =IFERROR(INDEX('Daily Schedule'!$Q$6:$Q$57,MATCH(A13,'Daily Schedule'!$A$6:$A$57,0)),"") -> COVERED | L13: =IF(E13="","NO ASSIGNEE",IF(AND(G13<>"",J13<>"",G13=J13),"VIOLATION – SAME LUNCH",IF(OR(K13="RELIEF GAP",K13="POSITION UNFILLED",K13=""),IF(OR(H13="",I13=""),"VIOLATION – NO RELIEF","CHECK MANUALLY"),IF(K13="COVERED","OK","CHECK MANUALLY")))) -> OK
A14: 25 | B14: =IFERROR(INDEX('Position Library'!$B$2:$B$53,MATCH(A14,'Position Library'!$A$2:$A$53,0)),"") -> North Security Checkpoint | C14: =IFERROR(INDEX('Position Library'!$C$2:$C$53,MATCH(A14,'Position Library'!$A$2:$A$53,0)),"") -> North Corridor | D14: =IFERROR(INDEX('Position Library'!$D$2:$D$53,MATCH(A14,'Position Library'!$A$2:$A$53,0)),"") -> Tier 1 | E14: =IFERROR(INDEX('Daily Schedule'!$F$6:$F$57,MATCH(A14,'Daily Schedule'!$A$6:$A$57,0)),"") -> EMP-0107 | F14: =IFERROR(INDEX('Daily Schedule'!$G$6:$G$57,MATCH(A14,'Daily Schedule'!$A$6:$A$57,0)),"") -> Moneshia Echols | G14: =IFERROR(INDEX('Daily Schedule'!$N$6:$N$57,MATCH(A14,'Daily Schedule'!$A$6:$A$57,0)),"") -> 9:00 AM | H14: =IFERROR(INDEX('Daily Schedule'!$O$6:$O$57,MATCH(A14,'Daily Schedule'!$A$6:$A$57,0)),"") -> 30 | I14: =IFERROR(INDEX('Daily Schedule'!$P$6:$P$57,MATCH(A14,'Daily Schedule'!$A$6:$A$57,0)),"") -> EMP-0073 | J14: =IF(I14="","",IFERROR(INDEX('Daily Schedule'!$N$6:$N$57,MATCH(I14,'Daily Schedule'!$G$6:$G$57,0)),IFERROR(INDEX('Daily Schedule'!$N$6:$N$57,MATCH(I14,'Daily Schedule'!$F$6:$F$57,0)),""))) -> 10:00 AM | K14: =IFERROR(INDEX('Daily Schedule'!$Q$6:$Q$57,MATCH(A14,'Daily Schedule'!$A$6:$A$57,0)),"") -> COVERED | L14: =IF(E14="","NO ASSIGNEE",IF(AND(G14<>"",J14<>"",G14=J14),"VIOLATION – SAME LUNCH",IF(OR(K14="RELIEF GAP",K14="POSITION UNFILLED",K14=""),IF(OR(H14="",I14=""),"VIOLATION – NO RELIEF","CHECK MANUALLY"),IF(K14="COVERED","OK","CHECK MANUALLY")))) -> OK
A15: 26 | B15: =IFERROR(INDEX('Position Library'!$B$2:$B$53,MATCH(A15,'Position Library'!$A$2:$A$53,0)),"") -> North Security Checkpoint | C15: =IFERROR(INDEX('Position Library'!$C$2:$C$53,MATCH(A15,'Position Library'!$A$2:$A$53,0)),"") -> North Restroom | D15: =IFERROR(INDEX('Position Library'!$D$2:$D$53,MATCH(A15,'Position Library'!$A$2:$A$53,0)),"") -> Tier 1 | E15: =IFERROR(INDEX('Daily Schedule'!$F$6:$F$57,MATCH(A15,'Daily Schedule'!$A$6:$A$57,0)),"") -> EMP-0112 | F15: =IFERROR(INDEX('Daily Schedule'!$G$6:$G$57,MATCH(A15,'Daily Schedule'!$A$6:$A$57,0)),"") -> Natasha Carbon | G15: =IFERROR(INDEX('Daily Schedule'!$N$6:$N$57,MATCH(A15,'Daily Schedule'!$A$6:$A$57,0)),"") -> 8:00 AM | H15: =IFERROR(INDEX('Daily Schedule'!$O$6:$O$57,MATCH(A15,'Daily Schedule'!$A$6:$A$57,0)),"") -> 27 | I15: =IFERROR(INDEX('Daily Schedule'!$P$6:$P$57,MATCH(A15,'Daily Schedule'!$A$6:$A$57,0)),"") -> EMP-0070 | J15: =IF(I15="","",IFERROR(INDEX('Daily Schedule'!$N$6:$N$57,MATCH(I15,'Daily Schedule'!$G$6:$G$57,0)),IFERROR(INDEX('Daily Schedule'!$N$6:$N$57,MATCH(I15,'Daily Schedule'!$F$6:$F$57,0)),""))) -> 9:00 AM | K15: =IFERROR(INDEX('Daily Schedule'!$Q$6:$Q$57,MATCH(A15,'Daily Schedule'!$A$6:$A$57,0)),"") -> COVERED | L15: =IF(E15="","NO ASSIGNEE",IF(AND(G15<>"",J15<>"",G15=J15),"VIOLATION – SAME LUNCH",IF(OR(K15="RELIEF GAP",K15="POSITION UNFILLED",K15=""),IF(OR(H15="",I15=""),"VIOLATION – NO RELIEF","CHECK MANUALLY"),IF(K15="COVERED","OK","CHECK MANUALLY")))) -> OK
A16: 32 | B16: =IFERROR(INDEX('Position Library'!$B$2:$B$53,MATCH(A16,'Position Library'!$A$2:$A$53,0)),"") -> Lower North Security Checkpoint | C16: =IFERROR(INDEX('Position Library'!$C$2:$C$53,MATCH(A16,'Position Library'!$A$2:$A$53,0)),"") -> Checkpoint – Inside | D16: =IFERROR(INDEX('Position Library'!$D$2:$D$53,MATCH(A16,'Position Library'!$A$2:$A$53,0)),"") -> Tier 1 | E16: =IFERROR(INDEX('Daily Schedule'!$F$6:$F$57,MATCH(A16,'Daily Schedule'!$A$6:$A$57,0)),"") -> EMP-0116 | F16: =IFERROR(INDEX('Daily Schedule'!$G$6:$G$57,MATCH(A16,'Daily Schedule'!$A$6:$A$57,0)),"") -> Phenica Peterson | G16: =IFERROR(INDEX('Daily Schedule'!$N$6:$N$57,MATCH(A16,'Daily Schedule'!$A$6:$A$57,0)),"") -> 8:00 AM | H16: =IFERROR(INDEX('Daily Schedule'!$O$6:$O$57,MATCH(A16,'Daily Schedule'!$A$6:$A$57,0)),"") -> 31 | I16: =IFERROR(INDEX('Daily Schedule'!$P$6:$P$57,MATCH(A16,'Daily Schedule'!$A$6:$A$57,0)),"") -> EMP-0041 | J16: =IF(I16="","",IFERROR(INDEX('Daily Schedule'!$N$6:$N$57,MATCH(I16,'Daily Schedule'!$G$6:$G$57,0)),IFERROR(INDEX('Daily Schedule'!$N$6:$N$57,MATCH(I16,'Daily Schedule'!$F$6:$F$57,0)),""))) -> 10:00 AM | K16: =IFERROR(INDEX('Daily Schedule'!$Q$6:$Q$57,MATCH(A16,'Daily Schedule'!$A$6:$A$57,0)),"") -> COVERED | L16: =IF(E16="","NO ASSIGNEE",IF(AND(G16<>"",J16<>"",G16=J16),"VIOLATION – SAME LUNCH",IF(OR(K16="RELIEF GAP",K16="POSITION UNFILLED",K16=""),IF(OR(H16="",I16=""),"VIOLATION – NO RELIEF","CHECK MANUALLY"),IF(K16="COVERED","OK","CHECK MANUALLY")))) -> OK
... A28: 52 | B28: =IFERROR(INDEX('Position Library'!$B$2:$B$53,MATCH(A28,'Position Library'!$A$2:$A$53,0)),"") -> Lower North Security Checkpoint | C28: =IFERROR(INDEX('Position Library'!$C$2:$C$53,MATCH(A28,'Position Library'!$A$2:$A$53,0)),"") -> Divest | D28: =IFERROR(INDEX('Position Library'!$D$2:$D$53,MATCH(A28,'Position Library'!$A$2:$A$53,0)),"") -> Tier 1 | E28: =IFERROR(INDEX('Daily Schedule'!$F$6:$F$57,MATCH(A28,'Daily Schedule'!$A$6:$A$57,0)),"") -> EMP-0054 | F28: =IFERROR(INDEX('Daily Schedule'!$G$6:$G$57,MATCH(A28,'Daily Schedule'!$A$6:$A$57,0)),"") -> Diane Nails | G28: =IFERROR(INDEX('Daily Schedule'!$N$6:$N$57,MATCH(A28,'Daily Schedule'!$A$6:$A$57,0)),"") -> 8:00 AM | H28: =IFERROR(INDEX('Daily Schedule'!$O$6:$O$57,MATCH(A28,'Daily Schedule'!$A$6:$A$57,0)),"") -> 42 | I28: =IFERROR(INDEX('Daily Schedule'!$P$6:$P$57,MATCH(A28,'Daily Schedule'!$A$6:$A$57,0)),"") -> EMP-0134 | J28: =IF(I28="","",IFERROR(INDEX('Daily Schedule'!$N$6:$N$57,MATCH(I28,'Daily Schedule'!$G$6:$G$57,0)),IFERROR(INDEX('Daily Schedule'!$N$6:$N$57,MATCH(I28,'Daily Schedule'!$F$6:$F$57,0)),""))) -> 9:00 AM | K28: =IFERROR(INDEX('Daily Schedule'!$Q$6:$Q$57,MATCH(A28,'Daily Schedule'!$A$6:$A$57,0)),"") -> COVERED | L28: =IF(E28="","NO ASSIGNEE",IF(AND(G28<>"",J28<>"",G28=J28),"VIOLATION – SAME LUNCH",IF(OR(K28="RELIEF GAP",K28="POSITION UNFILLED",K28=""),IF(OR(H28="",I28=""),"VIOLATION – NO RELIEF","CHECK MANUALLY"),IF(K28="COVERED","OK","CHECK MANUALLY")))) -> OK
A30: Legend:
A31: VIOLATION – SAME LUNCH = Primary and Relief share the same lunch window → Tier 1 uncovered during that hour
A32: VIOLATION – NO RELIEF = Tier 1 has an assignee but no relief person assigned
A33: OK = Break Coverage shows COVERED and lunches differ
A34: CHECK MANUALLY / NO ASSIGNEE = Review the Daily Schedule row for that position
A36: Action required when violations appear:
A37: 1. Change the Assigned Lunch of either the primary or the relief employee so the windows no longer overlap.
A38: 2. Or assign a different relief person who is free during the primary’s lunch window and is listed in the Position Relationships relief chain.
A39: 3. Re-run the schedule generation only after all CONFLICT FLAG cells show OK or acceptable status.

Sheet Full Coverage Board
A1: Full Position Coverage Board – All Positions with Break Relief by Name
A2: Shows every position, the assigned employee (by name), their lunch window, and the named break relief agent. Tier 1 rows are highlighted. Relief names come from the Daily Schedule; if a relief is missing the cell will be blank and flagged.
A4: Pos # | B4: Area | C4: Position Name | D4: Tier | E4: Assigned Employee | F4: Shift | G4: Assigned Lunch | H4: Break Relief Agent | I4: Relief From Position (Name) | J4: Relief Lunch | K4: Break Coverage | L4: Status
A5: ='Daily Schedule'!A6 -> 46 | B5: ='Daily Schedule'!B6 -> North Security Checkpoint | C5: ='Daily Schedule'!C6 -> Divest | D5: ='Daily Schedule'!D6 -> Tier 1 | E5: ='Daily Schedule'!G6 -> Ahamed John | F5: ='Daily Schedule'!H6 -> 3:45 AM | G5: ='Daily Schedule'!N6 -> 8:00 AM | H5: =IF('Daily Schedule'!P6="","",IF(LEFT('Daily Schedule'!P6,4)="EMP-",IFERROR(INDEX('Daily Workforce'!$C$6:$C$205,MATCH('Daily Schedule'!P6,'Daily Workforce'!$B$6:$B$205,0)),IFERROR(INDEX('Employee Master'!$B$2:$B$159,MATCH('Daily Schedule'!P6,'Employee Master'!$A$2:$A$159,0)),'Daily Schedule'!P6)),'Daily Schedule'!P6)) -> Jamal Reynolds | I5: =IF('Daily Schedule'!O6="","",IFERROR(INDEX('Daily Schedule'!$C$6:$C$57,MATCH('Daily Schedule'!O6,'Daily Schedule'!$A$6:$A$57,0)),IFERROR(INDEX('Position Library'!$C$2:$C$53,MATCH('Daily Schedule'!O6,'Position Library'!$A$2:$A$53,0)),'Daily Schedule'!O6))) -> MSC Escalator | J5: =IF('Daily Schedule'!P6="","",IFERROR(INDEX('Daily Schedule'!$N$6:$N$57,MATCH(IF(LEFT('Daily Schedule'!P6,4)="EMP-",IFERROR(INDEX('Daily Workforce'!$C$6:$C$205,MATCH('Daily Schedule'!P6,'Daily Workforce'!$B$6:$B$205,0)),'Daily Schedule'!P6),'Daily Schedule'!P6),'Daily Schedule'!$G$6:$G$57,0)),IFERROR(INDEX('Daily Schedule'!$N$6:$N$57,MATCH('Daily Schedule'!P6,'Daily Schedule'!$F$6:$F$57,0)),""))) -> 9:00 AM | K5: ='Daily Schedule'!Q6 -> COVERED | L5: =IF('Daily Schedule'!G6="","UNFILLED",IF(AND('Daily Schedule'!N6<>"",J5<>"",'Daily Schedule'!N6=J5),"SAME LUNCH",IF(AND('Daily Schedule'!D6="Tier 1",OR('Daily Schedule'!P6="",'Daily Schedule'!Q6="RELIEF GAP")),"NO RELIEF",IF('Daily Schedule'!Q6="COVERED","OK",IF('Daily Schedule'!Q6="","CHECK",'Daily Schedule'!Q6))))) -> OK
A6: ='Daily Schedule'!A7 -> 47 | B6: ='Daily Schedule'!B7 -> North Security Checkpoint | C6: ='Daily Schedule'!C7 -> Divest | D6: ='Daily Schedule'!D7 -> Tier 1 | E6: ='Daily Schedule'!G7 -> Allen Suggs | F6: ='Daily Schedule'!H7 -> 3:45 AM | G6: ='Daily Schedule'!N7 -> 8:00 AM | H6: =IF('Daily Schedule'!P7="","",IF(LEFT('Daily Schedule'!P7,4)="EMP-",IFERROR(INDEX('Daily Workforce'!$C$6:$C$205,MATCH('Daily Schedule'!P7,'Daily Workforce'!$B$6:$B$205,0)),IFERROR(INDEX('Employee Master'!$B$2:$B$159,MATCH('Daily Schedule'!P7,'Employee Master'!$A$2:$A$159,0)),'Daily Schedule'!P7)),'Daily Schedule'!P7)) -> Jada Batiste | I6: =IF('Daily Schedule'!O7="","",IFERROR(INDEX('Daily Schedule'!$C$6:$C$57,MATCH('Daily Schedule'!O7,'Daily Schedule'!$A$6:$A$57,0)),IFERROR(INDEX('Position Library'!$C$2:$C$53,MATCH('Daily Schedule'!O7,'Position Library'!$A$2:$A$53,0)),'Daily Schedule'!O7))) -> MSC Escalator | J6: =IF('Daily Schedule'!P7="","",IFERROR(INDEX('Daily Schedule'!$N$6:$N$57,MATCH(IF(LEFT('Daily Schedule'!P7,4)="EMP-",IFERROR(INDEX('Daily Workforce'!$C$6:$C$205,MATCH('Daily Schedule'!P7,'Daily Workforce'!$B$6:$B$205,0)),'Daily Schedule'!P7),'Daily Schedule'!P7),'Daily Schedule'!$G$6:$G$57,0)),IFERROR(INDEX('Daily Schedule'!$N$6:$N$57,MATCH('Daily Schedule'!P7,'Daily Schedule'!$F$6:$F$57,0)),""))) -> 10:00 AM | K6: ='Daily Schedule'!Q7 -> COVERED | L6: =IF('Daily Schedule'!G7="","UNFILLED",IF(AND('Daily Schedule'!N7<>"",J6<>"",'Daily Schedule'!N7=J6),"SAME LUNCH",IF(AND('Daily Schedule'!D7="Tier 1",OR('Daily Schedule'!P7="",'Daily Schedule'!Q7="RELIEF GAP")),"NO RELIEF",IF('Daily Schedule'!Q7="COVERED","OK",IF('Daily Schedule'!Q7="","CHECK",'Daily Schedule'!Q7))))) -> OK
A7: ='Daily Schedule'!A8 -> 48 | B7: ='Daily Schedule'!B8 -> North Security Checkpoint | C7: ='Daily Schedule'!C8 -> Divest | D7: ='Daily Schedule'!D8 -> Tier 1 | E7: ='Daily Schedule'!G8 -> Benjamin Crosby | F7: ='Daily Schedule'!H8 -> 3:45 AM | G7: ='Daily Schedule'!N8 -> 9:00 AM | H7: =IF('Daily Schedule'!P8="","",IF(LEFT('Daily Schedule'!P8,4)="EMP-",IFERROR(INDEX('Daily Workforce'!$C$6:$C$205,MATCH('Daily Schedule'!P8,'Daily Workforce'!$B$6:$B$205,0)),IFERROR(INDEX('Employee Master'!$B$2:$B$159,MATCH('Daily Schedule'!P8,'Employee Master'!$A$2:$A$159,0)),'Daily Schedule'!P8)),'Daily Schedule'!P8)) -> Linton Brereton | I7: =IF('Daily Schedule'!O8="","",IFERROR(INDEX('Daily Schedule'!$C$6:$C$57,MATCH('Daily Schedule'!O8,'Daily Schedule'!$A$6:$A$57,0)),IFERROR(INDEX('Position Library'!$C$2:$C$53,MATCH('Daily Schedule'!O8,'Position Library'!$A$2:$A$53,0)),'Daily Schedule'!O8))) -> KIA | J7: =IF('Daily Schedule'!P8="","",IFERROR(INDEX('Daily Schedule'!$N$6:$N$57,MATCH(IF(LEFT('Daily Schedule'!P8,4)="EMP-",IFERROR(INDEX('Daily Workforce'!$C$6:$C$205,MATCH('Daily Schedule'!P8,'Daily Workforce'!$B$6:$B$205,0)),'Daily Schedule'!P8),'Daily Schedule'!P8),'Daily Schedule'!$G$6:$G$57,0)),IFERROR(INDEX('Daily Schedule'!$N$6:$N$57,MATCH('Daily Schedule'!P8,'Daily Schedule'!$F$6:$F$57,0)),""))) -> 9:00 AM | K7: ='Daily Schedule'!Q8 -> COVERED | L7: =IF('Daily Schedule'!G8="","UNFILLED",IF(AND('Daily Schedule'!N8<>"",J7<>"",'Daily Schedule'!N8=J7),"SAME LUNCH",IF(AND('Daily Schedule'!D8="Tier 1",OR('Daily Schedule'!P8="",'Daily Schedule'!Q8="RELIEF GAP")),"NO RELIEF",IF('Daily Schedule'!Q8="COVERED","OK",IF('Daily Schedule'!Q8="","CHECK",'Daily Schedule'!Q8))))) -> SAME LUNCH
A8: ='Daily Schedule'!A9 -> 49 | B8: ='Daily Schedule'!B9 -> North Security Checkpoint | C8: ='Daily Schedule'!C9 -> Divest | D8: ='Daily Schedule'!D9 -> Tier 1 | E8: ='Daily Schedule'!G9 -> Crosby Pavon-Lacayo | F8: ='Daily Schedule'!H9 -> 3:45 AM | G8: ='Daily Schedule'!N9 -> 8:00 AM | H8: =IF('Daily Schedule'!P9="","",IF(LEFT('Daily Schedule'!P9,4)="EMP-",IFERROR(INDEX('Daily Workforce'!$C$6:$C$205,MATCH('Daily Schedule'!P9,'Daily Workforce'!$B$6:$B$205,0)),IFERROR(INDEX('Employee Master'!$B$2:$B$159,MATCH('Daily Schedule'!P9,'Employee Master'!$A$2:$A$159,0)),'Daily Schedule'!P9)),'Daily Schedule'!P9)) -> Mildred Tarres | I8: =IF('Daily Schedule'!O9="","",IFERROR(INDEX('Daily Schedule'!$C$6:$C$57,MATCH('Daily Schedule'!O9,'Daily Schedule'!$A$6:$A$57,0)),IFERROR(INDEX('Position Library'!$C$2:$C$53,MATCH('Daily Schedule'!O9,'Position Library'!$A$2:$A$53,0)),'Daily Schedule'!O9))) -> Piedmont / West Crossover | J8: =IF('Daily Schedule'!P9="","",IFERROR(INDEX('Daily Schedule'!$N$6:$N$57,MATCH(IF(LEFT('Daily Schedule'!P9,4)="EMP-",IFERROR(INDEX('Daily Workforce'!$C$6:$C$205,MATCH('Daily Schedule'!P9,'Daily Workforce'!$B$6:$B$205,0)),'Daily Schedule'!P9),'Daily Schedule'!P9),'Daily Schedule'!$G$6:$G$57,0)),IFERROR(INDEX('Daily Schedule'!$N$6:$N$57,MATCH('Daily Schedule'!P9,'Daily Schedule'!$F$6:$F$57,0)),""))) -> 9:00 AM | K8: ='Daily Schedule'!Q9 -> COVERED | L8: =IF('Daily Schedule'!G9="","UNFILLED",IF(AND('Daily Schedule'!N9<>"",J8<>"",'Daily Schedule'!N9=J8),"SAME LUNCH",IF(AND('Daily Schedule'!D9="Tier 1",OR('Daily Schedule'!P9="",'Daily Schedule'!Q9="RELIEF GAP")),"NO RELIEF",IF('Daily Schedule'!Q9="COVERED","OK",IF('Daily Schedule'!Q9="","CHECK",'Daily Schedule'!Q9))))) -> OK
A9: ='Daily Schedule'!A10 -> 50 | B9: ='Daily Schedule'!B10 -> Lower North Security Checkpoint | C9: ='Daily Schedule'!C10 -> Divest | D9: ='Daily Schedule'!D10 -> Tier 1 | E9: ='Daily Schedule'!G10 -> Danielle Holmes | F9: ='Daily Schedule'!H10 -> 3:45 AM | G9: ='Daily Schedule'!N10 -> 8:00 AM | H9: =IF('Daily Schedule'!P10="","",IF(LEFT('Daily Schedule'!P10,4)="EMP-",IFERROR(INDEX('Daily Workforce'!$C$6:$C$205,MATCH('Daily Schedule'!P10,'Daily Workforce'!$B$6:$B$205,0)),IFERROR(INDEX('Employee Master'!$B$2:$B$159,MATCH('Daily Schedule'!P10,'Employee Master'!$A$2:$A$159,0)),'Daily Schedule'!P10)),'Daily Schedule'!P10)) -> Kidest Solomon | I9: =IF('Daily Schedule'!O10="","",IFERROR(INDEX('Daily Schedule'!$C$6:$C$57,MATCH('Daily Schedule'!O10,'Daily Schedule'!$A$6:$A$57,0)),IFERROR(INDEX('Position Library'!$C$2:$C$53,MATCH('Daily Schedule'!O10,'Position Library'!$A$2:$A$53,0)),'Daily Schedule'!O10))) -> KIA | J9: =IF('Daily Schedule'!P10="","",IFERROR(INDEX('Daily Schedule'!$N$6:$N$57,MATCH(IF(LEFT('Daily Schedule'!P10,4)="EMP-",IFERROR(INDEX('Daily Workforce'!$C$6:$C$205,MATCH('Daily Schedule'!P10,'Daily Workforce'!$B$6:$B$205,0)),'Daily Schedule'!P10),'Daily Schedule'!P10),'Daily Schedule'!$G$6:$G$57,0)),IFERROR(INDEX('Daily Schedule'!$N$6:$N$57,MATCH('Daily Schedule'!P10,'Daily Schedule'!$F$6:$F$57,0)),""))) -> 10:00 AM | K9: ='Daily Schedule'!Q10 -> COVERED | L9: =IF('Daily Schedule'!G10="","UNFILLED",IF(AND('Daily Schedule'!N10<>"",J9<>"",'Daily Schedule'!N10=J9),"SAME LUNCH",IF(AND('Daily Schedule'!D10="Tier 1",OR('Daily Schedule'!P10="",'Daily Schedule'!Q10="RELIEF GAP")),"NO RELIEF",IF('Daily Schedule'!Q10="COVERED","OK",IF('Daily Schedule'!Q10="","CHECK",'Daily Schedule'!Q10))))) -> OK
A10: ='Daily Schedule'!A11 -> 51 | B10: ='Daily Schedule'!B11 -> Lower North Security Checkpoint | C10: ='Daily Schedule'!C11 -> Divest | D10: ='Daily Schedule'!D11 -> Tier 1 | E10: ='Daily Schedule'!G11 -> Demetrius Thomas | F10: ='Daily Schedule'!H11 -> 3:45 AM | G10: ='Daily Schedule'!N11 -> 9:00 AM | H10: =IF('Daily Schedule'!P11="","",IF(LEFT('Daily Schedule'!P11,4)="EMP-",IFERROR(INDEX('Daily Workforce'!$C$6:$C$205,MATCH('Daily Schedule'!P11,'Daily Workforce'!$B$6:$B$205,0)),IFERROR(INDEX('Employee Master'!$B$2:$B$159,MATCH('Daily Schedule'!P11,'Employee Master'!$A$2:$A$159,0)),'Daily Schedule'!P11)),'Daily Schedule'!P11)) -> Sara Alemu | I10: =IF('Daily Schedule'!O11="","",IFERROR(INDEX('Daily Schedule'!$C$6:$C$57,MATCH('Daily Schedule'!O11,'Daily Schedule'!$A$6:$A$57,0)),IFERROR(INDEX('Position Library'!$C$2:$C$53,MATCH('Daily Schedule'!O11,'Position Library'!$A$2:$A$53,0)),'Daily Schedule'!O11))) -> TGIF / West Crossover | J10: =IF('Daily Schedule'!P11="","",IFERROR(INDEX('Daily Schedule'!$N$6:$N$57,MATCH(IF(LEFT('Daily Schedule'!P11,4)="EMP-",IFERROR(INDEX('Daily Workforce'!$C$6:$C$205,MATCH('Daily Schedule'!P11,'Daily Workforce'!$B$6:$B$205,0)),'Daily Schedule'!P11),'Daily Schedule'!P11),'Daily Schedule'!$G$6:$G$57,0)),IFERROR(INDEX('Daily Schedule'!$N$6:$N$57,MATCH('Daily Schedule'!P11,'Daily Schedule'!$F$6:$F$57,0)),""))) -> 9:00 AM | K10: ='Daily Schedule'!Q11 -> COVERED | L10: =IF('Daily Schedule'!G11="","UNFILLED",IF(AND('Daily Schedule'!N11<>"",J10<>"",'Daily Schedule'!N11=J10),"SAME LUNCH",IF(AND('Daily Schedule'!D11="Tier 1",OR('Daily Schedule'!P11="",'Daily Schedule'!Q11="RELIEF GAP")),"NO RELIEF",IF('Daily Schedule'!Q11="COVERED","OK",IF('Daily Schedule'!Q11="","CHECK",'Daily Schedule'!Q11))))) -> SAME LUNCH
A11: ='Daily Schedule'!A12 -> 52 | B11: ='Daily Schedule'!B12 -> Lower North Security Checkpoint | C11: ='Daily Schedule'!C12 -> Divest | D11: ='Daily Schedule'!D12 -> Tier 1 | E11: ='Daily Schedule'!G12 -> Diane Nails | F11: ='Daily Schedule'!H12 -> 3:45 AM | G11: ='Daily Schedule'!N12 -> 8:00 AM | H11: =IF('Daily Schedule'!P12="","",IF(LEFT('Daily Schedule'!P12,4)="EMP-",IFERROR(INDEX('Daily Workforce'!$C$6:$C$205,MATCH('Daily Schedule'!P12,'Daily Workforce'!$B$6:$B$205,0)),IFERROR(INDEX('Employee Master'!$B$2:$B$159,MATCH('Daily Schedule'!P12,'Employee Master'!$A$2:$A$159,0)),'Daily Schedule'!P12)),'Daily Schedule'!P12)) -> Shawanda Webb | I11: =IF('Daily Schedule'!O12="","",IFERROR(INDEX('Daily Schedule'!$C$6:$C$57,MATCH('Daily Schedule'!O12,'Daily Schedule'!$A$6:$A$57,0)),IFERROR(INDEX('Position Library'!$C$2:$C$53,MATCH('Daily Schedule'!O12,'Position Library'!$A$2:$A$53,0)),'Daily Schedule'!O12))) -> Bravo West | J11: =IF('Daily Schedule'!P12="","",IFERROR(INDEX('Daily Schedule'!$N$6:$N$57,MATCH(IF(LEFT('Daily Schedule'!P12,4)="EMP-",IFERROR(INDEX('Daily Workforce'!$C$6:$C$205,MATCH('Daily Schedule'!P12,'Daily Workforce'!$B$6:$B$205,0)),'Daily Schedule'!P12),'Daily Schedule'!P12),'Daily Schedule'!$G$6:$G$57,0)),IFERROR(INDEX('Daily Schedule'!$N$6:$N$57,MATCH('Daily Schedule'!P12,'Daily Schedule'!$F$6:$F$57,0)),""))) -> 9:00 AM | K11: ='Daily Schedule'!Q12 -> COVERED | L11: =IF('Daily Schedule'!G12="","UNFILLED",IF(AND('Daily Schedule'!N12<>"",J11<>"",'Daily Schedule'!N12=J11),"SAME LUNCH",IF(AND('Daily Schedule'!D12="Tier 1",OR('Daily Schedule'!P12="",'Daily Schedule'!Q12="RELIEF GAP")),"NO RELIEF",IF('Daily Schedule'!Q12="COVERED","OK",IF('Daily Schedule'!Q12="","CHECK",'Daily Schedule'!Q12))))) -> OK
A12: ='Daily Schedule'!A13 -> 1 | B12: ='Daily Schedule'!B13 -> Main Security Checkpoint | C12: ='Daily Schedule'!C13 -> Front Entrance | D12: ='Daily Schedule'!D13 -> Tier 1 | E12: ='Daily Schedule'!G13 -> Emonnie Dorsey | F12: ='Daily Schedule'!H13 -> 3:45 AM | G12: ='Daily Schedule'!N13 -> 8:00 AM | H12: =IF('Daily Schedule'!P13="","",IF(LEFT('Daily Schedule'!P13,4)="EMP-",IFERROR(INDEX('Daily Workforce'!$C$6:$C$205,MATCH('Daily Schedule'!P13,'Daily Workforce'!$B$6:$B$205,0)),IFERROR(INDEX('Employee Master'!$B$2:$B$159,MATCH('Daily Schedule'!P13,'Employee Master'!$A$2:$A$159,0)),'Daily Schedule'!P13)),'Daily Schedule'!P13)) -> Ashia Norman | I12: =IF('Daily Schedule'!O13="","",IFERROR(INDEX('Daily Schedule'!$C$6:$C$57,MATCH('Daily Schedule'!O13,'Daily Schedule'!$A$6:$A$57,0)),IFERROR(INDEX('Position Library'!$C$2:$C$53,MATCH('Daily Schedule'!O13,'Position Library'!$A$2:$A$53,0)),'Daily Schedule'!O13))) -> Front Entrance | J12: =IF('Daily Schedule'!P13="","",IFERROR(INDEX('Daily Schedule'!$N$6:$N$57,MATCH(IF(LEFT('Daily Schedule'!P13,4)="EMP-",IFERROR(INDEX('Daily Workforce'!$C$6:$C$205,MATCH('Daily Schedule'!P13,'Daily Workforce'!$B$6:$B$205,0)),'Daily Schedule'!P13),'Daily Schedule'!P13),'Daily Schedule'!$G$6:$G$57,0)),IFERROR(INDEX('Daily Schedule'!$N$6:$N$57,MATCH('Daily Schedule'!P13,'Daily Schedule'!$F$6:$F$57,0)),""))) -> 9:00 AM | K12: ='Daily Schedule'!Q13 -> COVERED | L12: =IF('Daily Schedule'!G13="","UNFILLED",IF(AND('Daily Schedule'!N13<>"",J12<>"",'Daily Schedule'!N13=J12),"SAME LUNCH",IF(AND('Daily Schedule'!D13="Tier 1",OR('Daily Schedule'!P13="",'Daily Schedule'!Q13="RELIEF GAP")),"NO RELIEF",IF('Daily Schedule'!Q13="COVERED","OK",IF('Daily Schedule'!Q13="","CHECK",'Daily Schedule'!Q13))))) -> OK
A13: ='Daily Schedule'!A14 -> 2 | B13: ='Daily Schedule'!B14 -> Main Security Checkpoint | C13: ='Daily Schedule'!C14 -> ADA Entrance | D13: ='Daily Schedule'!D14 -> Tier 1 | E13: ='Daily Schedule'!G14 -> Haddyjatou Ndure | F13: ='Daily Schedule'!H14 -> 3:45 AM | G13: ='Daily Schedule'!N14 -> 9:00 AM | H13: =IF('Daily Schedule'!P14="","",IF(LEFT('Daily Schedule'!P14,4)="EMP-",IFERROR(INDEX('Daily Workforce'!$C$6:$C$205,MATCH('Daily Schedule'!P14,'Daily Workforce'!$B$6:$B$205,0)),IFERROR(INDEX('Employee Master'!$B$2:$B$159,MATCH('Daily Schedule'!P14,'Employee Master'!$A$2:$A$159,0)),'Daily Schedule'!P14)),'Daily Schedule'!P14)) | I13: =IF('Daily Schedule'!O14="","",IFERROR(INDEX('Daily Schedule'!$C$6:$C$57,MATCH('Daily Schedule'!O14,'Daily Schedule'!$A$6:$A$57,0)),IFERROR(INDEX('Position Library'!$C$2:$C$53,MATCH('Daily Schedule'!O14,'Position Library'!$A$2:$A$53,0)),'Daily Schedule'!O14))) | J13: =IF('Daily Schedule'!P14="","",IFERROR(INDEX('Daily Schedule'!$N$6:$N$57,MATCH(IF(LEFT('Daily Schedule'!P14,4)="EMP-",IFERROR(INDEX('Daily Workforce'!$C$6:$C$205,MATCH('Daily Schedule'!P14,'Daily Workforce'!$B$6:$B$205,0)),'Daily Schedule'!P14),'Daily Schedule'!P14),'Daily Schedule'!$G$6:$G$57,0)),IFERROR(INDEX('Daily Schedule'!$N$6:$N$57,MATCH('Daily Schedule'!P14,'Daily Schedule'!$F$6:$F$57,0)),""))) | K13: ='Daily Schedule'!Q14 -> RELIEF GAP | L13: =IF('Daily Schedule'!G14="","UNFILLED",IF(AND('Daily Schedule'!N14<>"",J13<>"",'Daily Schedule'!N14=J13),"SAME LUNCH",IF(AND('Daily Schedule'!D14="Tier 1",OR('Daily Schedule'!P14="",'Daily Schedule'!Q14="RELIEF GAP")),"NO RELIEF",IF('Daily Schedule'!Q14="COVERED","OK",IF('Daily Schedule'!Q14="","CHECK",'Daily Schedule'!Q14))))) -> NO RELIEF
A14: ='Daily Schedule'!A15 -> 4 | B14: ='Daily Schedule'!B15 -> Main Security Checkpoint | C14: ='Daily Schedule'!C15 -> Inside Center | D14: ='Daily Schedule'!D15 -> Tier 1 | E14: ='Daily Schedule'!G15 | F14: ='Daily Schedule'!H15 | G14: ='Daily Schedule'!N15 | H14: =IF('Daily Schedule'!P15="","",IF(LEFT('Daily Schedule'!P15,4)="EMP-",IFERROR(INDEX('Daily Workforce'!$C$6:$C$205,MATCH('Daily Schedule'!P15,'Daily Workforce'!$B$6:$B$205,0)),IFERROR(INDEX('Employee Master'!$B$2:$B$159,MATCH('Daily Schedule'!P15,'Employee Master'!$A$2:$A$159,0)),'Daily Schedule'!P15)),'Daily Schedule'!P15)) -> Kelon Arnold | I14: =IF('Daily Schedule'!O15="","",IFERROR(INDEX('Daily Schedule'!$C$6:$C$57,MATCH('Daily Schedule'!O15,'Daily Schedule'!$A$6:$A$57,0)),IFERROR(INDEX('Position Library'!$C$2:$C$53,MATCH('Daily Schedule'!O15,'Position Library'!$A$2:$A$53,0)),'Daily Schedule'!O15))) -> Lanes 1 - 3 / Pre-Check | J14: =IF('Daily Schedule'!P15="","",IFERROR(INDEX('Daily Schedule'!$N$6:$N$57,MATCH(IF(LEFT('Daily Schedule'!P15,4)="EMP-",IFERROR(INDEX('Daily Workforce'!$C$6:$C$205,MATCH('Daily Schedule'!P15,'Daily Workforce'!$B$6:$B$205,0)),'Daily Schedule'!P15),'Daily Schedule'!P15),'Daily Schedule'!$G$6:$G$57,0)),IFERROR(INDEX('Daily Schedule'!$N$6:$N$57,MATCH('Daily Schedule'!P15,'Daily Schedule'!$F$6:$F$57,0)),""))) -> 8:00 AM | K14: ='Daily Schedule'!Q15 -> POSITION UNFILLED | L14: =IF('Daily Schedule'!G15="","UNFILLED",IF(AND('Daily Schedule'!N15<>"",J14<>"",'Daily Schedule'!N15=J14),"SAME LUNCH",IF(AND('Daily Schedule'!D15="Tier 1",OR('Daily Schedule'!P15="",'Daily Schedule'!Q15="RELIEF GAP")),"NO RELIEF",IF('Daily Schedule'!Q15="COVERED","OK",IF('Daily Schedule'!Q15="","CHECK",'Daily Schedule'!Q15))))) -> UNFILLED
A15: ='Daily Schedule'!A16 -> 5 | B15: ='Daily Schedule'!B16 -> Main Security Checkpoint | C15: ='Daily Schedule'!C16 -> Lanes 1 - 3 / Pre-Check | D15: ='Daily Schedule'!D16 -> Tier 1 | E15: ='Daily Schedule'!G16 -> Kelon Arnold | F15: ='Daily Schedule'!H16 -> 3:45 AM | G15: ='Daily Schedule'!N16 -> 8:00 AM | H15: =IF('Daily Schedule'!P16="","",IF(LEFT('Daily Schedule'!P16,4)="EMP-",IFERROR(INDEX('Daily Workforce'!$C$6:$C$205,MATCH('Daily Schedule'!P16,'Daily Workforce'!$B$6:$B$205,0)),IFERROR(INDEX('Employee Master'!$B$2:$B$159,MATCH('Daily Schedule'!P16,'Employee Master'!$A$2:$A$159,0)),'Daily Schedule'!P16)),'Daily Schedule'!P16)) -> Aleah Mckinnon | I15: =IF('Daily Schedule'!O16="","",IFERROR(INDEX('Daily Schedule'!$C$6:$C$57,MATCH('Daily Schedule'!O16,'Daily Schedule'!$A$6:$A$57,0)),IFERROR(INDEX('Position Library'!$C$2:$C$53,MATCH('Daily Schedule'!O16,'Position Library'!$A$2:$A$53,0)),'Daily Schedule'!O16))) -> Lanes 17 - 18 | J15: =IF('Daily Schedule'!P16="","",IFERROR(INDEX('Daily Schedule'!$N$6:$N$57,MATCH(IF(LEFT('Daily Schedule'!P16,4)="EMP-",IFERROR(INDEX('Daily Workforce'!$C$6:$C$205,MATCH('Daily Schedule'!P16,'Daily Workforce'!$B$6:$B$205,0)),'Daily Schedule'!P16),'Daily Schedule'!P16),'Daily Schedule'!$G$6:$G$57,0)),IFERROR(INDEX('Daily Schedule'!$N$6:$N$57,MATCH('Daily Schedule'!P16,'Daily Schedule'!$F$6:$F$57,0)),""))) -> 10:00 AM | K15: ='Daily Schedule'!Q16 -> COVERED | L15: =IF('Daily Schedule'!G16="","UNFILLED",IF(AND('Daily Schedule'!N16<>"",J15<>"",'Daily Schedule'!N16=J15),"SAME LUNCH",IF(AND('Daily Schedule'!D16="Tier 1",OR('Daily Schedule'!P16="",'Daily Schedule'!Q16="RELIEF GAP")),"NO RELIEF",IF('Daily Schedule'!Q16="COVERED","OK",IF('Daily Schedule'!Q16="","CHECK",'Daily Schedule'!Q16))))) -> OK
A16: ='Daily Schedule'!A17 -> 8 | B16: ='Daily Schedule'!B17 -> Main Security Checkpoint | C16: ='Daily Schedule'!C17 -> Inside Center | D16: ='Daily Schedule'!D17 -> Tier 1 | E16: ='Daily Schedule'!G17 | F16: ='Daily Schedule'!H17 | G16: ='Daily Schedule'!N17 | H16: =IF('Daily Schedule'!P17="","",IF(LEFT('Daily Schedule'!P17,4)="EMP-",IFERROR(INDEX('Daily Workforce'!$C$6:$C$205,MATCH('Daily Schedule'!P17,'Daily Workforce'!$B$6:$B$205,0)),IFERROR(INDEX('Employee Master'!$B$2:$B$159,MATCH('Daily Schedule'!P17,'Employee Master'!$A$2:$A$159,0)),'Daily Schedule'!P17)),'Daily Schedule'!P17)) -> Aleah Mckinnon | I16: =IF('Daily Schedule'!O17="","",IFERROR(INDEX('Daily Schedule'!$C$6:$C$57,MATCH('Daily Schedule'!O17,'Daily Schedule'!$A$6:$A$57,0)),IFERROR(INDEX('Position Library'!$C$2:$C$53,MATCH('Daily Schedule'!O17,'Position Library'!$A$2:$A$53,0)),'Daily Schedule'!O17))) -> Lanes 17 - 18 | J16: =IF('Daily Schedule'!P17="","",IFERROR(INDEX('Daily Schedule'!$N$6:$N$57,MATCH(IF(LEFT('Daily Schedule'!P17,4)="EMP-",IFERROR(INDEX('Daily Workforce'!$C$6:$C$205,MATCH('Daily Schedule'!P17,'Daily Workforce'!$B$6:$B$205,0)),'Daily Schedule'!P17),'Daily Schedule'!P17),'Daily Schedule'!$G$6:$G$57,0)),IFERROR(INDEX('Daily Schedule'!$N$6:$N$57,MATCH('Daily Schedule'!P17,'Daily Schedule'!$F$6:$F$57,0)),""))) -> 10:00 AM | K16: ='Daily Schedule'!Q17 -> POSITION UNFILLED | L16: =IF('Daily Schedule'!G17="","UNFILLED",IF(AND('Daily Schedule'!N17<>"",J16<>"",'Daily Schedule'!N17=J16),"SAME LUNCH",IF(AND('Daily Schedule'!D17="Tier 1",OR('Daily Schedule'!P17="",'Daily Schedule'!Q17="RELIEF GAP")),"NO RELIEF",IF('Daily Schedule'!Q17="COVERED","OK",IF('Daily Schedule'!Q17="","CHECK",'Daily Schedule'!Q17))))) -> UNFILLED
... A56: ='Daily Schedule'!A57 -> 44 | B56: ='Daily Schedule'!B57 -> AGT Level | C56: ='Daily Schedule'!C57 -> Delta West | D56: ='Daily Schedule'!D57 -> Tier 4 | E56: ='Daily Schedule'!G57 -> Vanessa Cortes | F56: ='Daily Schedule'!H57 -> 5:45 AM | G56: ='Daily Schedule'!N57 -> 10:00 AM | H56: =IF('Daily Schedule'!P57="","",IF(LEFT('Daily Schedule'!P57,4)="EMP-",IFERROR(INDEX('Daily Workforce'!$C$6:$C$205,MATCH('Daily Schedule'!P57,'Daily Workforce'!$B$6:$B$205,0)),IFERROR(INDEX('Employee Master'!$B$2:$B$159,MATCH('Daily Schedule'!P57,'Employee Master'!$A$2:$A$159,0)),'Daily Schedule'!P57)),'Daily Schedule'!P57)) | I56: =IF('Daily Schedule'!O57="","",IFERROR(INDEX('Daily Schedule'!$C$6:$C$57,MATCH('Daily Schedule'!O57,'Daily Schedule'!$A$6:$A$57,0)),IFERROR(INDEX('Position Library'!$C$2:$C$53,MATCH('Daily Schedule'!O57,'Position Library'!$A$2:$A$53,0)),'Daily Schedule'!O57))) | J56: =IF('Daily Schedule'!P57="","",IFERROR(INDEX('Daily Schedule'!$N$6:$N$57,MATCH(IF(LEFT('Daily Schedule'!P57,4)="EMP-",IFERROR(INDEX('Daily Workforce'!$C$6:$C$205,MATCH('Daily Schedule'!P57,'Daily Workforce'!$B$6:$B$205,0)),'Daily Schedule'!P57),'Daily Schedule'!P57),'Daily Schedule'!$G$6:$G$57,0)),IFERROR(INDEX('Daily Schedule'!$N$6:$N$57,MATCH('Daily Schedule'!P57,'Daily Schedule'!$F$6:$F$57,0)),""))) | K56: ='Daily Schedule'!Q57 -> NOT REQUIRED | L56: =IF('Daily Schedule'!G57="","UNFILLED",IF(AND('Daily Schedule'!N57<>"",J56<>"",'Daily Schedule'!N57=J56),"SAME LUNCH",IF(AND('Daily Schedule'!D57="Tier 1",OR('Daily Schedule'!P57="",'Daily Schedule'!Q57="RELIEF GAP")),"NO RELIEF",IF('Daily Schedule'!Q57="COVERED","OK",IF('Daily Schedule'!Q57="","CHECK",'Daily Schedule'!Q57))))) -> NOT REQUIRED
A58: Legend / Status meanings:
A59: OK | B59: Primary has coverage and (if relief exists) lunches do not overlap
A60: SAME LUNCH | B60: Primary and Break Relief Agent share the same lunch window → position uncovered during that hour
A61: NO RELIEF | B61: Tier 1 position has an assignee but no named break relief agent
A62: UNFILLED | B62: No employee currently assigned to this position
A63: RELIEF GAP / other | B63: See Break Coverage column and Daily Schedule for details
A65: Note: Tier 1 positions (mandatory coverage) appear with orange-tinted rows after you open the file in Excel if you apply a filter or conditional format on the Tier column = "Tier 1".

Sheet Employee Master
A1: Employee ID | B1: Employee Name | C1: Shift | D1: Days Off | E1: Lead | F1: Mentor | G1: Active | H1: Lunch Preference | I1: Shift Group | K1: Shift Order
A2: EMP-0001 | B2: Aaliyah Snider | C2: 2:00 PM | D2: Wed, Thu | E2: N | F2: N | G2: Y | H2: None | I2: =IF(C2="","",IF(OR(C2="3:45 AM",C2="5:45 AM"),"AM",IF(OR(C2="12:15 PM",C2="2:00 PM"),"PM","Overnight"))) -> PM | K2: =IF(C2="","",IF(C2="3:45 AM",1,IF(C2="5:45 AM",2,IF(C2="12:15 PM",3,IF(C2="2:00 PM",4,IF(C2="9:15 PM",5,"")))))) -> 4
A3: EMP-0002 | B3: Abdou Mballo | C3: 5:45 AM | D3: Mon, Tue, Wed, Thu, Fri | E3: N | F3: N | G3: Y | H3: None | I3: =IF(C3="","",IF(OR(C3="3:45 AM",C3="5:45 AM"),"AM",IF(OR(C3="12:15 PM",C3="2:00 PM"),"PM","Overnight"))) -> AM | K3: =IF(C3="","",IF(C3="3:45 AM",1,IF(C3="5:45 AM",2,IF(C3="12:15 PM",3,IF(C3="2:00 PM",4,IF(C3="9:15 PM",5,"")))))) -> 2
A4: EMP-0003 | B4: Abebe Ambaye | C4: 5:45 AM | D4: Sat, Sun | E4: Y | F4: N | G4: Y | H4: None | I4: =IF(C4="","",IF(OR(C4="3:45 AM",C4="5:45 AM"),"AM",IF(OR(C4="12:15 PM",C4="2:00 PM"),"PM","Overnight"))) -> AM | K4: =IF(C4="","",IF(C4="3:45 AM",1,IF(C4="5:45 AM",2,IF(C4="12:15 PM",3,IF(C4="2:00 PM",4,IF(C4="9:15 PM",5,"")))))) -> 2
A5: EMP-0004 | B5: Adeyeye Opaaje | C5: 5:45 AM | D5: Sat, Sun | E5: N | F5: N | G5: Y | H5: None | I5: =IF(C5="","",IF(OR(C5="3:45 AM",C5="5:45 AM"),"AM",IF(OR(C5="12:15 PM",C5="2:00 PM"),"PM","Overnight"))) -> AM | K5: =IF(C5="","",IF(C5="3:45 AM",1,IF(C5="5:45 AM",2,IF(C5="12:15 PM",3,IF(C5="2:00 PM",4,IF(C5="9:15 PM",5,"")))))) -> 2
A6: EMP-0005 | B6: Adrian Franklin | C6: 12:15 PM | D6: Sun, Mon | E6: Y | F6: N | G6: Y | H6: None | I6: =IF(C6="","",IF(OR(C6="3:45 AM",C6="5:45 AM"),"AM",IF(OR(C6="12:15 PM",C6="2:00 PM"),"PM","Overnight"))) -> PM | K6: =IF(C6="","",IF(C6="3:45 AM",1,IF(C6="5:45 AM",2,IF(C6="12:15 PM",3,IF(C6="2:00 PM",4,IF(C6="9:15 PM",5,"")))))) -> 3
A7: EMP-0006 | B7: Agnes Bammannage | C7: 12:15 PM | D7: Fri, Sat | E7: N | F7: N | G7: Y | H7: None | I7: =IF(C7="","",IF(OR(C7="3:45 AM",C7="5:45 AM"),"AM",IF(OR(C7="12:15 PM",C7="2:00 PM"),"PM","Overnight"))) -> PM | K7: =IF(C7="","",IF(C7="3:45 AM",1,IF(C7="5:45 AM",2,IF(C7="12:15 PM",3,IF(C7="2:00 PM",4,IF(C7="9:15 PM",5,"")))))) -> 3
A8: EMP-0007 | B8: Ahamed John | C8: 3:45 AM | D8: Thu, Fri | E8: N | F8: N | G8: Y | H8: None | I8: =IF(C8="","",IF(OR(C8="3:45 AM",C8="5:45 AM"),"AM",IF(OR(C8="12:15 PM",C8="2:00 PM"),"PM","Overnight"))) -> AM | K8: =IF(C8="","",IF(C8="3:45 AM",1,IF(C8="5:45 AM",2,IF(C8="12:15 PM",3,IF(C8="2:00 PM",4,IF(C8="9:15 PM",5,"")))))) -> 1
A9: EMP-0008 | B9: Akuugo Nduaguba | C9: 2:00 PM | D9: Wed, Thu | E9: N | F9: N | G9: Y | H9: None | I9: =IF(C9="","",IF(OR(C9="3:45 AM",C9="5:45 AM"),"AM",IF(OR(C9="12:15 PM",C9="2:00 PM"),"PM","Overnight"))) -> PM | K9: =IF(C9="","",IF(C9="3:45 AM",1,IF(C9="5:45 AM",2,IF(C9="12:15 PM",3,IF(C9="2:00 PM",4,IF(C9="9:15 PM",5,"")))))) -> 4
A10: EMP-0009 | B10: Aleah Mckinnon | C10: 5:45 AM | D10: Thu, Fri | E10: N | F10: N | G10: Y | H10: None | I10: =IF(C10="","",IF(OR(C10="3:45 AM",C10="5:45 AM"),"AM",IF(OR(C10="12:15 PM",C10="2:00 PM"),"PM","Overnight"))) -> AM | K10: =IF(C10="","",IF(C10="3:45 AM",1,IF(C10="5:45 AM",2,IF(C10="12:15 PM",3,IF(C10="2:00 PM",4,IF(C10="9:15 PM",5,"")))))) -> 2
A11: EMP-0010 | B11: Allen Suggs | C11: 3:45 AM | D11: Fri, Sat | E11: N | F11: N | G11: Y | H11: None | I11: =IF(C11="","",IF(OR(C11="3:45 AM",C11="5:45 AM"),"AM",IF(OR(C11="12:15 PM",C11="2:00 PM"),"PM","Overnight"))) -> AM | K11: =IF(C11="","",IF(C11="3:45 AM",1,IF(C11="5:45 AM",2,IF(C11="12:15 PM",3,IF(C11="2:00 PM",4,IF(C11="9:15 PM",5,"")))))) -> 1
A12: EMP-0011 | B12: Alyssa Prince | C12: 12:15 PM | D12: Wed, Thu | E12: N | F12: N | G12: Y | H12: None | I12: =IF(C12="","",IF(OR(C12="3:45 AM",C12="5:45 AM"),"AM",IF(OR(C12="12:15 PM",C12="2:00 PM"),"PM","Overnight"))) -> PM | K12: =IF(C12="","",IF(C12="3:45 AM",1,IF(C12="5:45 AM",2,IF(C12="12:15 PM",3,IF(C12="2:00 PM",4,IF(C12="9:15 PM",5,"")))))) -> 3
A13: EMP-0012 | B13: Amadou Diallo | C13: 12:15 PM | D13: Thu, Fri | E13: N | F13: N | G13: Y | H13: None | I13: =IF(C13="","",IF(OR(C13="3:45 AM",C13="5:45 AM"),"AM",IF(OR(C13="12:15 PM",C13="2:00 PM"),"PM","Overnight"))) -> PM | K13: =IF(C13="","",IF(C13="3:45 AM",1,IF(C13="5:45 AM",2,IF(C13="12:15 PM",3,IF(C13="2:00 PM",4,IF(C13="9:15 PM",5,"")))))) -> 3
... A20: EMP-0019 | B20: Ashley Lazenby | C20: 2:00 PM | D20: Wed, Thu | E20: N | F20: N | G20: Y | H20: None | I20: =IF(C20="","",IF(OR(C20="3:45 AM",C20="5:45 AM"),"AM",IF(OR(C20="12:15 PM",C20="2:00 PM"),"PM","Overnight"))) -> PM | K20: =IF(C20="","",IF(C20="3:45 AM",1,IF(C20="5:45 AM",2,IF(C20="12:15 PM",3,IF(C20="2:00 PM",4,IF(C20="9:15 PM",5,"")))))) -> 4
A21: EMP-0020 | B21: Ashtin Keys | C21: 9:15 PM | E21: N | F21: N | G21: Y | H21: None | I21: =IF(C21="","",IF(OR(C21="3:45 AM",C21="5:45 AM"),"AM",IF(OR(C21="12:15 PM",C21="2:00 PM"),"PM","Overnight"))) -> Overnight | K21: =IF(C21="","",IF(C21="3:45 AM",1,IF(C21="5:45 AM",2,IF(C21="12:15 PM",3,IF(C21="2:00 PM",4,IF(C21="9:15 PM",5,"")))))) -> 5
A22: EMP-0021 | B22: Auniyah Bell | C22: 2:00 PM | D22: Mon, Tue | E22: Y | F22: N | G22: Y | H22: None | I22: =IF(C22="","",IF(OR(C22="3:45 AM",C22="5:45 AM"),"AM",IF(OR(C22="12:15 PM",C22="2:00 PM"),"PM","Overnight"))) -> PM | K22: =IF(C22="","",IF(C22="3:45 AM",1,IF(C22="5:45 AM",2,IF(C22="12:15 PM",3,IF(C22="2:00 PM",4,IF(C22="9:15 PM",5,"")))))) -> 4
A23: EMP-0022 | B23: Benjamin Crosby | C23: 3:45 AM | D23: Wed, Thu | E23: N | F23: N | G23: Y | H23: None | I23: =IF(C23="","",IF(OR(C23="3:45 AM",C23="5:45 AM"),"AM",IF(OR(C23="12:15 PM",C23="2:00 PM"),"PM","Overnight"))) -> AM | K23: =IF(C23="","",IF(C23="3:45 AM",1,IF(C23="5:45 AM",2,IF(C23="12:15 PM",3,IF(C23="2:00 PM",4,IF(C23="9:15 PM",5,"")))))) -> 1
A24: EMP-0023 | B24: Betelhem Wubshet | C24: 12:15 PM | D24: Mon, Tue | E24: N | F24: N | G24: Y | H24: None | I24: =IF(C24="","",IF(OR(C24="3:45 AM",C24="5:45 AM"),"AM",IF(OR(C24="12:15 PM",C24="2:00 PM"),"PM","Overnight"))) -> PM | K24: =IF(C24="","",IF(C24="3:45 AM",1,IF(C24="5:45 AM",2,IF(C24="12:15 PM",3,IF(C24="2:00 PM",4,IF(C24="9:15 PM",5,"")))))) -> 3
A25: EMP-0024 | B25: Beverly Felton | C25: 3:45 AM | D25: Sun, Mon, Tue | E25: N | F25: N | G25: Y | H25: None | I25: =IF(C25="","",IF(OR(C25="3:45 AM",C25="5:45 AM"),"AM",IF(OR(C25="12:15 PM",C25="2:00 PM"),"PM","Overnight"))) -> AM | K25: =IF(C25="","",IF(C25="3:45 AM",1,IF(C25="5:45 AM",2,IF(C25="12:15 PM",3,IF(C25="2:00 PM",4,IF(C25="9:15 PM",5,"")))))) -> 1
A26: EMP-0025 | B26: Bintou Gueye | C26: 5:45 AM | D26: Mon, Tue | E26: N | F26: N | G26: Y | H26: None | I26: =IF(C26="","",IF(OR(C26="3:45 AM",C26="5:45 AM"),"AM",IF(OR(C26="12:15 PM",C26="2:00 PM"),"PM","Overnight"))) -> AM | K26: =IF(C26="","",IF(C26="3:45 AM",1,IF(C26="5:45 AM",2,IF(C26="12:15 PM",3,IF(C26="2:00 PM",4,IF(C26="9:15 PM",5,"")))))) -> 2
A27: EMP-0026 | B27: Birhanu Hailu | C27: 5:45 AM | D27: Thu, Fri | E27: N | F27: N | G27: Y | H27: None | I27: =IF(C27="","",IF(OR(C27="3:45 AM",C27="5:45 AM"),"AM",IF(OR(C27="12:15 PM",C27="2:00 PM"),"PM","Overnight"))) -> AM | K27: =IF(C27="","",IF(C27="3:45 AM",1,IF(C27="5:45 AM",2,IF(C27="12:15 PM",3,IF(C27="2:00 PM",4,IF(C27="9:15 PM",5,"")))))) -> 2
A28: EMP-0027 | B28: Braheem Wooden | C28: 2:00 PM | D28: Tue, Wed | E28: N | F28: N | G28: Y | H28: None | I28: =IF(C28="","",IF(OR(C28="3:45 AM",C28="5:45 AM"),"AM",IF(OR(C28="12:15 PM",C28="2:00 PM"),"PM","Overnight"))) -> PM | K28: =IF(C28="","",IF(C28="3:45 AM",1,IF(C28="5:45 AM",2,IF(C28="12:15 PM",3,IF(C28="2:00 PM",4,IF(C28="9:15 PM",5,"")))))) -> 4
A29: EMP-0028 | B29: Brain Lee | C29: 5:45 AM | D29: Thu, Fri | E29: N | F29: N | G29: Y | H29: None | I29: =IF(C29="","",IF(OR(C29="3:45 AM",C29="5:45 AM"),"AM",IF(OR(C29="12:15 PM",C29="2:00 PM"),"PM","Overnight"))) -> AM | K29: =IF(C29="","",IF(C29="3:45 AM",1,IF(C29="5:45 AM",2,IF(C29="12:15 PM",3,IF(C29="2:00 PM",4,IF(C29="9:15 PM",5,"")))))) -> 2
A30: EMP-0029 | B30: Brianna Bryant | C30: 3:45 AM | D30: Tue, Wed | E30: N | F30: N | G30: Y | H30: None | I30: =IF(C30="","",IF(OR(C30="3:45 AM",C30="5:45 AM"),"AM",IF(OR(C30="12:15 PM",C30="2:00 PM"),"PM","Overnight"))) -> AM | K30: =IF(C30="","",IF(C30="3:45 AM",1,IF(C30="5:45 AM",2,IF(C30="12:15 PM",3,IF(C30="2:00 PM",4,IF(C30="9:15 PM",5,"")))))) -> 1
A31: EMP-0030 | B31: Brittany Gaither | C31: 2:00 PM | D31: Mon, Tue | E31: N | F31: N | G31: Y | H31: None | I31: =IF(C31="","",IF(OR(C31="3:45 AM",C31="5:45 AM"),"AM",IF(OR(C31="12:15 PM",C31="2:00 PM"),"PM","Overnight"))) -> PM | K31: =IF(C31="","",IF(C31="3:45 AM",1,IF(C31="5:45 AM",2,IF(C31="12:15 PM",3,IF(C31="2:00 PM",4,IF(C31="9:15 PM",5,"")))))) -> 4
A32: EMP-0031 | B32: Brittney Quave | C32: 12:15 PM | D32: Thu, Fri | E32: N | F32: N | G32: Y | H32: None | I32: =IF(C32="","",IF(OR(C32="3:45 AM",C32="5:45 AM"),"AM",IF(OR(C32="12:15 PM",C32="2:00 PM"),"PM","Overnight"))) -> PM | K32: =IF(C32="","",IF(C32="3:45 AM",1,IF(C32="5:45 AM",2,IF(C32="12:15 PM",3,IF(C32="2:00 PM",4,IF(C32="9:15 PM",5,"")))))) -> 3
A33: EMP-0032 | B33: Camille Muhammad | C33: 9:15 PM | E33: N | F33: N | G33: Y | H33: None | I33: =IF(C33="","",IF(OR(C33="3:45 AM",C33="5:45 AM"),"AM",IF(OR(C33="12:15 PM",C33="2:00 PM"),"PM","Overnight"))) -> Overnight | K33: =IF(C33="","",IF(C33="3:45 AM",1,IF(C33="5:45 AM",2,IF(C33="12:15 PM",3,IF(C33="2:00 PM",4,IF(C33="9:15 PM",5,"")))))) -> 5
A34: EMP-0033 | B34: Camille Underwood | C34: 9:15 PM | E34: N | F34: N | G34: Y | H34: None | I34: =IF(C34="","",IF(OR(C34="3:45 AM",C34="5:45 AM"),"AM",IF(OR(C34="12:15 PM",C34="2:00 PM"),"PM","Overnight"))) -> Overnight | K34: =IF(C34="","",IF(C34="3:45 AM",1,IF(C34="5:45 AM",2,IF(C34="12:15 PM",3,IF(C34="2:00 PM",4,IF(C34="9:15 PM",5,"")))))) -> 5
A35: EMP-0034 | B35: Carrie Weaver | C35: 12:15 PM | D35: Sat, Sun | E35: N | F35: N | G35: Y | H35: None | I35: =IF(C35="","",IF(OR(C35="3:45 AM",C35="5:45 AM"),"AM",IF(OR(C35="12:15 PM",C35="2:00 PM"),"PM","Overnight"))) -> PM | K35: =IF(C35="","",IF(C35="3:45 AM",1,IF(C35="5:45 AM",2,IF(C35="12:15 PM",3,IF(C35="2:00 PM",4,IF(C35="9:15 PM",5,"")))))) -> 3
A36: EMP-0035 | B36: Cathy Foster | C36: 3:45 AM | D36: Mon, Tue | E36: Y | F36: N | G36: Y | H36: None | I36: =IF(C36="","",IF(OR(C36="3:45 AM",C36="5:45 AM"),"AM",IF(OR(C36="12:15 PM",C36="2:00 PM"),"PM","Overnight"))) -> AM | K36: =IF(C36="","",IF(C36="3:45 AM",1,IF(C36="5:45 AM",2,IF(C36="12:15 PM",3,IF(C36="2:00 PM",4,IF(C36="9:15 PM",5,"")))))) -> 1
A37: EMP-0036 | B37: Cheikh Sylla | C37: 2:00 PM | D37: Thu, Fri | E37: N | F37: N | G37: Y | H37: None | I37: =IF(C37="","",IF(OR(C37="3:45 AM",C37="5:45 AM"),"AM",IF(OR(C37="12:15 PM",C37="2:00 PM"),"PM","Overnight"))) -> PM | K37: =IF(C37="","",IF(C37="3:45 AM",1,IF(C37="5:45 AM",2,IF(C37="12:15 PM",3,IF(C37="2:00 PM",4,IF(C37="9:15 PM",5,"")))))) -> 4
A38: EMP-0037 | B38: Chiedu Memeh | C38: 12:15 PM | D38: Fri, Sat | E38: N | F38: N | G38: Y | H38: None | I38: =IF(C38="","",IF(OR(C38="3:45 AM",C38="5:45 AM"),"AM",IF(OR(C38="12:15 PM",C38="2:00 PM"),"PM","Overnight"))) -> PM | K38: =IF(C38="","",IF(C38="3:45 AM",1,IF(C38="5:45 AM",2,IF(C38="12:15 PM",3,IF(C38="2:00 PM",4,IF(C38="9:15 PM",5,"")))))) -> 3
A39: EMP-0038 | B39: Chris Jungson | C39: 2:00 PM | D39: Mon, Tue | E39: N | F39: N | G39: Y | H39: None | I39: =IF(C39="","",IF(OR(C39="3:45 AM",C39="5:45 AM"),"AM",IF(OR(C39="12:15 PM",C39="2:00 PM"),"PM","Overnight"))) -> PM | K39: =IF(C39="","",IF(C39="3:45 AM",1,IF(C39="5:45 AM",2,IF(C39="12:15 PM",3,IF(C39="2:00 PM",4,IF(C39="9:15 PM",5,"")))))) -> 4
A40: EMP-0039 | B40: Christopher White | C40: 2:00 PM | D40: Sun, Mon | E40: N | F40: N | G40: Y | H40: None | I40: =IF(C40="","",IF(OR(C40="3:45 AM",C40="5:45 AM"),"AM",IF(OR(C40="12:15 PM",C40="2:00 PM"),"PM","Overnight"))) -> PM | K40: =IF(C40="","",IF(C40="3:45 AM",1,IF(C40="5:45 AM",2,IF(C40="12:15 PM",3,IF(C40="2:00 PM",4,IF(C40="9:15 PM",5,"")))))) -> 4
A41: EMP-0040 | B41: Chrystal Harvey | C41: 5:45 AM | D41: Thu, Fri | E41: N | F41: N | G41: Y | H41: None | I41: =IF(C41="","",IF(OR(C41="3:45 AM",C41="5:45 AM"),"AM",IF(OR(C41="12:15 PM",C41="2:00 PM"),"PM","Overnight"))) -> AM | K41: =IF(C41="","",IF(C41="3:45 AM",1,IF(C41="5:45 AM",2,IF(C41="12:15 PM",3,IF(C41="2:00 PM",4,IF(C41="9:15 PM",5,"")))))) -> 2
A42: EMP-0041 | B42: Cicely Thicklin | C42: 5:45 AM | D42: Sat, Sun | E42: N | F42: N | G42: Y | H42: None | I42: =IF(C42="","",IF(OR(C42="3:45 AM",C42="5:45 AM"),"AM",IF(OR(C42="12:15 PM",C42="2:00 PM"),"PM","Overnight"))) -> AM | K42: =IF(C42="","",IF(C42="3:45 AM",1,IF(C42="5:45 AM",2,IF(C42="12:15 PM",3,IF(C42="2:00 PM",4,IF(C42="9:15 PM",5,"")))))) -> 2
A43: EMP-0042 | B43: Crosby Pavon-Lacayo | C43: 3:45 AM | D43: Wed, Thu | E43: N | F43: N | G43: Y | H43: None | I43: =IF(C43="","",IF(OR(C43="3:45 AM",C43="5:45 AM"),"AM",IF(OR(C43="12:15 PM",C43="2:00 PM"),"PM","Overnight"))) -> AM | K43: =IF(C43="","",IF(C43="3:45 AM",1,IF(C43="5:45 AM",2,IF(C43="12:15 PM",3,IF(C43="2:00 PM",4,IF(C43="9:15 PM",5,"")))))) -> 1
